{
	"registryname": "less_functional_part_builder",
	"localizedname": "Less Functional Part Builder",
	"requires-blueprint": true,
	"parts": [
		{
			"x": -3,
			"y": 0,
			"z": 3,
			"elements": [
				"modularmachinery:blockoutputbus@6"
			]
		},
		{
			"x": 0,
			"y": 2,
			"z": 3,
			"elements": [
				"extrautils2:ironwood_log@3"
			]
		},
		{
			"x": -3,
			"y": 0,
			"z": 0,
			"elements": [
				"modularmachinery:blockinputbus@6"
			]
		},
		{
			"x": 0,
			"y": 0,
			"z": 3,
			"elements": [
				"modularmachinery:blockenergyinputhatch@7"
			]
		},
		{
			"x": -3,
			"y": 3,
			"z": 0,
			"elements": [
				"extrautils2:ironwood_planks@0"
			]
		},
		{
			"x": -2,
			"y": 3,
			"z": 0,
			"elements": [
				"extrautils2:ironwood_planks@0"
			]
		},
		{
			"x": -3,
			"y": 3,
			"z": 1,
			"elements": [
				"extrautils2:ironwood_planks@0"
			]
		},
		{
			"x": -1,
			"y": 3,
			"z": 0,
			"elements": [
				"extrautils2:ironwood_planks@0"
			]
		},
		{
			"x": -3,
			"y": 1,
			"z": 0,
			"elements": [
				"extrautils2:ironwood_log@3"
			]
		},
		{
			"x": -2,
			"y": 3,
			"z": 1,
			"elements": [
				"extrautils2:ironwood_planks@0"
			]
		},
		{
			"x": -3,
			"y": 3,
			"z": 2,
			"elements": [
				"extrautils2:ironwood_planks@0"
			]
		},
		{
			"x": 0,
			"y": 3,
			"z": 0,
			"elements": [
				"extrautils2:ironwood_planks@0"
			]
		},
		{
			"x": -1,
			"y": 3,
			"z": 1,
			"elements": [
				"extrautils2:ironwood_planks@0"
			]
		},
		{
			"x": -2,
			"y": 3,
			"z": 2,
			"elements": [
				"extrautils2:ironwood_planks@0"
			]
		},
		{
			"x": -3,
			"y": 3,
			"z": 3,
			"elements": [
				"extrautils2:ironwood_planks@0"
			]
		},
		{
			"x": 0,
			"y": 3,
			"z": 1,
			"elements": [
				"extrautils2:ironwood_planks@0"
			]
		},
		{
			"x": -1,
			"y": 3,
			"z": 2,
			"elements": [
				"extrautils2:ironwood_planks@0"
			]
		},
		{
			"x": -2,
			"y": 3,
			"z": 3,
			"elements": [
				"extrautils2:ironwood_planks@0"
			]
		},
		{
			"x": 0,
			"y": 3,
			"z": 2,
			"elements": [
				"extrautils2:ironwood_planks@0"
			]
		},
		{
			"x": 0,
			"y": 1,
			"z": 0,
			"elements": [
				"extrautils2:ironwood_log@3"
			]
		},
		{
			"x": -3,
			"y": 1,
			"z": 3,
			"elements": [
				"extrautils2:ironwood_log@3"
			]
		},
		{
			"x": -1,
			"y": 3,
			"z": 3,
			"elements": [
				"extrautils2:ironwood_planks@0"
			]
		},
		{
			"x": 0,
			"y": 3,
			"z": 3,
			"elements": [
				"extrautils2:ironwood_planks@0"
			]
		},
		{
			"x": 0,
			"y": 1,
			"z": 3,
			"elements": [
				"extrautils2:ironwood_log@3"
			]
		},
		{
			"x": -3,
			"y": 4,
			"z": 0,
			"elements": [
				"minecraft:light_weighted_pressure_plate@0"
			]
		},
		{
			"x": -2,
			"y": 4,
			"z": 0,
			"elements": [
				"minecraft:light_weighted_pressure_plate@0"
			]
		},
		{
			"x": -3,
			"y": 4,
			"z": 1,
			"elements": [
				"minecraft:light_weighted_pressure_plate@0"
			]
		},
		{
			"x": -3,
			"y": 2,
			"z": 0,
			"elements": [
				"extrautils2:ironwood_log@3"
			]
		},
		{
			"x": -1,
			"y": 4,
			"z": 0,
			"elements": [
				"minecraft:light_weighted_pressure_plate@0"
			]
		},
		{
			"x": -2,
			"y": 4,
			"z": 2,
			"elements": [
				"minecraft:light_weighted_pressure_plate@0"
			]
		},
		{
			"x": 0,
			"y": 4,
			"z": 1,
			"elements": [
				"minecraft:light_weighted_pressure_plate@0"
			]
		},
		{
			"x": -3,
			"y": 2,
			"z": 3,
			"elements": [
				"extrautils2:ironwood_log@3"
			]
		},
		{
			"x": -1,
			"y": 4,
			"z": 3,
			"elements": [
				"minecraft:light_weighted_pressure_plate@0"
			]
		},
		{
			"x": 0,
			"y": 4,
			"z": 2,
			"elements": [
				"minecraft:light_weighted_pressure_plate@0"
			]
		},
		{
			"x": 0,
			"y": 2,
			"z": 0,
			"elements": [
				"extrautils2:ironwood_log@3"
			]
		},
		{
			"x": 0,
			"y": 4,
			"z": 3,
			"elements": [
				"minecraft:light_weighted_pressure_plate@0"
			]
		}
	]
}