{
	"registryname": "entity_bundler",
	"localizedname": "Entity Bundler",
	"parts": [{
			"elements": ["modularmachinery:blockenergyinputhatch@7"],
			"x": -2,
			"y": 0,
			"z": 2
		}, {
			"elements": ["mysticalagriculture:ingot_storage@6"],
			"x": -1,
			"y": 0,
			"z": 0
		}, {
			"elements": ["mysticalagriculture:ingot_storage@6"],
			"x": -2,
			"y": 0,
			"z": 0
		}, {
			"elements": ["extendedcrafting:trimmed@5"],
			"x": 2,
			"y": 2,
			"z": 1
		}, {
			"elements": ["mysticalagriculture:ingot_storage@6"],
			"x": 1,
			"y": 0,
			"z": 0
		}, {
			"elements": ["extrautils2:simpledecorative@0"],
			"x": -1,
			"y": 0,
			"z": 2
		}, {
			"elements": ["extrautils2:simpledecorative@1"],
			"x": 0,
			"y": 0,
			"z": 2
		}, {
			"elements": ["mysticalagriculture:ingot_storage@6"],
			"x": 2,
			"y": 0,
			"z": 0
		}, {
			"elements": ["mysticalagriculture:ingot_storage@6"],
			"x": -2,
			"y": 0,
			"z": 4
		}, {
			"elements": ["extendedcrafting:trimmed@5"],
			"x": 2,
			"y": 2,
			"z": 3
		}, {
			"elements": ["extrautils2:simpledecorative@0"],
			"x": 1,
			"y": 0,
			"z": 2
		}, {
			"elements": ["mysticalagriculture:ingot_storage@6"],
			"x": -1,
			"y": 0,
			"z": 4
		}, {
			"elements": ["modularmachinery:blockinputbus@6"],
			"x": 2,
			"y": 0,
			"z": 2
		}, {
			"elements": ["modularmachinery:blockfluidinputhatch@7"],
			"x": 0,
			"y": 0,
			"z": 4
		}, {
			"elements": ["mysticalagriculture:ingot_storage@6"],
			"x": 1,
			"y": 0,
			"z": 4
		}, {
			"elements": ["mysticalagriculture:ingot_storage@6"],
			"x": 2,
			"y": 0,
			"z": 4
		}, {
			"elements": ["minecraft:purpur_block@0"],
			"x": -2,
			"y": 3,
			"z": 1
		}, {
			"elements": ["actuallyadditions:block_display_stand@0"],
			"x": -2,
			"y": 1,
			"z": 0
		}, {
			"elements": ["mysticalagriculture:growth_accelerator@0"],
			"x": -1,
			"y": 3,
			"z": 1
		}, {
			"elements": ["actuallyadditions:block_giant_chest_large@0"],
			"x": -1,
			"y": 1,
			"z": 0
		}, {
			"elements": ["minecraft:purpur_block@0"],
			"x": -2,
			"y": 3,
			"z": 3
		}, {
			"elements": ["minecraft:purpur_block@0"],
			"x": 0,
			"y": 3,
			"z": 1
		}, {
			"elements": ["mysticalagriculture:growth_accelerator@0"],
			"x": 1,
			"y": 3,
			"z": 1
		}, {
			"elements": ["modularmachinery:blockoutputbus@6"],
			"x": 0,
			"y": 1,
			"z": 0
		}, {
			"elements": ["actuallyadditions:block_giant_chest_large@0"],
			"x": -2,
			"y": 1,
			"z": 2
		}, {
			"elements": ["mysticalagriculture:growth_accelerator@0"],
			"x": -1,
			"y": 3,
			"z": 3
		}, {
			"elements": ["minecraft:purpur_block@0"],
			"x": 0,
			"y": 3,
			"z": 3
		}, {
			"elements": ["minecraft:purpur_block@0"],
			"x": 2,
			"y": 3,
			"z": 1
		}, {
			"elements": ["actuallyadditions:block_giant_chest_large@0"],
			"x": 1,
			"y": 1,
			"z": 0
		}, {
			"elements": ["mysticalagriculture:growth_accelerator@0"],
			"x": 1,
			"y": 3,
			"z": 3
		}, {
			"elements": ["extendedcrafting:pedestal@0"],
			"x": 0,
			"y": 1,
			"z": 2
		}, {
			"elements": ["actuallyadditions:block_display_stand@0"],
			"x": 2,
			"y": 1,
			"z": 0
		}, {
			"elements": ["actuallyadditions:block_display_stand@0"],
			"x": -2,
			"y": 1,
			"z": 4
		}, {
			"elements": ["actuallyadditions:block_giant_chest_large@0"],
			"x": -1,
			"y": 1,
			"z": 4
		}, {
			"elements": ["minecraft:purpur_block@0"],
			"x": 2,
			"y": 3,
			"z": 3
		}, {
			"elements": ["actuallyadditions:block_giant_chest_large@0"],
			"x": 0,
			"y": 1,
			"z": 4
		}, {
			"elements": ["actuallyadditions:block_giant_chest_large@0"],
			"x": 2,
			"y": 1,
			"z": 2
		}, {
			"elements": ["actuallyadditions:block_giant_chest_large@0"],
			"x": 1,
			"y": 1,
			"z": 4
		}, {
			"elements": ["actuallyadditions:block_display_stand@0"],
			"x": 2,
			"y": 1,
			"z": 4
		}, {
			"elements": ["extendedcrafting:trimmed@5"],
			"x": -2,
			"y": 2,
			"z": 0
		}, {
			"elements": ["enderio:block_experience_obelisk@0"],
			"x": -1,
			"y": 4,
			"z": 1
		}, {
			"elements": ["extendedcrafting:trimmed@5"],
			"x": -1,
			"y": 2,
			"z": 0
		}, {
			"elements": ["extendedcrafting:storage@3"],
			"x": 0,
			"y": 4,
			"z": 1
		}, {
			"elements": ["enderio:block_experience_obelisk@0"],
			"x": 1,
			"y": 4,
			"z": 1
		}, {
			"elements": ["extendedcrafting:trimmed@5"],
			"x": 0,
			"y": 2,
			"z": 0
		}, {
			"elements": ["extendedcrafting:trimmed@5"],
			"x": -2,
			"y": 2,
			"z": 2
		}, {
			"elements": ["enderio:block_experience_obelisk@0"],
			"x": -1,
			"y": 4,
			"z": 3
		}, {
			"elements": ["mysticalagriculture:ingot_storage@6"],
			"x": -2,
			"y": 0,
			"z": 1
		}, {
			"elements": ["extendedcrafting:storage@3"],
			"x": 0,
			"y": 4,
			"z": 3
		}, {
			"elements": ["extendedcrafting:trimmed@5"],
			"x": 1,
			"y": 2,
			"z": 0
		}, {
			"elements": ["enderio:block_experience_obelisk@0"],
			"x": 1,
			"y": 4,
			"z": 3
		}, {
			"elements": ["extendedcrafting:trimmed@5"],
			"x": 2,
			"y": 2,
			"z": 0
		}, {
			"elements": ["extrautils2:simpledecorative@2"],
			"x": -1,
			"y": 0,
			"z": 1
		}, {
			"elements": ["extendedcrafting:trimmed@5"],
			"x": -2,
			"y": 2,
			"z": 4
		}, {
			"elements": ["extrautils2:simpledecorative@0"],
			"x": 0,
			"y": 0,
			"z": 1
		}, {
			"elements": ["mysticalagriculture:ingot_storage@6"],
			"x": -2,
			"y": 0,
			"z": 3
		}, {
			"elements": ["extendedcrafting:trimmed@5"],
			"x": -1,
			"y": 2,
			"z": 4
		}, {
			"elements": ["extendedcrafting:trimmed@5"],
			"x": 0,
			"y": 2,
			"z": 4
		}, {
			"elements": ["extendedcrafting:trimmed@5"],
			"x": 2,
			"y": 2,
			"z": 2
		}, {
			"elements": ["extrautils2:simpledecorative@2"],
			"x": 1,
			"y": 0,
			"z": 1
		}, {
			"elements": ["extrautils2:simpledecorative@2"],
			"x": -1,
			"y": 0,
			"z": 3
		}, {
			"elements": ["mysticalagriculture:ingot_storage@6"],
			"x": 2,
			"y": 0,
			"z": 1
		}, {
			"elements": ["extrautils2:simpledecorative@0"],
			"x": 0,
			"y": 0,
			"z": 3
		}, {
			"elements": ["extendedcrafting:trimmed@5"],
			"x": 1,
			"y": 2,
			"z": 4
		}, {
			"elements": ["extendedcrafting:trimmed@5"],
			"x": 2,
			"y": 2,
			"z": 4
		}, {
			"elements": ["extrautils2:simpledecorative@2"],
			"x": 1,
			"y": 0,
			"z": 3
		}, {
			"elements": ["mysticalagriculture:ingot_storage@6"],
			"x": 2,
			"y": 0,
			"z": 3
		}, {
			"elements": ["mysticalagriculture:growth_accelerator@0"],
			"x": -2,
			"y": 3,
			"z": 0
		}, {
			"elements": ["minecraft:purpur_block@0"],
			"x": -1,
			"y": 3,
			"z": 0
		}, {
			"elements": ["mysticalagriculture:growth_accelerator@0"],
			"x": -2,
			"y": 3,
			"z": 2
		}, {
			"elements": ["mysticalagriculture:growth_accelerator@0"],
			"x": 0,
			"y": 3,
			"z": 0
		}, {
			"elements": ["minecraft:purpur_block@0"],
			"x": 1,
			"y": 3,
			"z": 0
		}, {
			"elements": ["actuallyadditions:block_giant_chest_large@0"],
			"x": -2,
			"y": 1,
			"z": 1
		}, {
			"elements": ["minecraft:purpur_block@0"],
			"x": -1,
			"y": 3,
			"z": 2
		}, {
			"elements": ["mysticalagriculture:growth_accelerator@0"],
			"x": -2,
			"y": 3,
			"z": 4
		}, {
			"elements": ["mysticalagriculture:growth_accelerator@0"],
			"x": 0,
			"y": 3,
			"z": 2
		}, {
			"elements": ["mysticalagriculture:growth_accelerator@0"],
			"x": 2,
			"y": 3,
			"z": 0
		}, {
			"elements": ["minecraft:purpur_block@0"],
			"x": 1,
			"y": 3,
			"z": 2
		}, {
			"elements": ["actuallyadditions:block_giant_chest_large@0"],
			"x": -2,
			"y": 1,
			"z": 3
		}, {
			"elements": ["minecraft:purpur_block@0"],
			"x": -1,
			"y": 3,
			"z": 4
		}, {
			"elements": ["mysticalagriculture:growth_accelerator@0"],
			"x": 0,
			"y": 3,
			"z": 4
		}, {
			"elements": ["mysticalagriculture:growth_accelerator@0"],
			"x": 2,
			"y": 3,
			"z": 2
		}, {
			"elements": ["minecraft:purpur_block@0"],
			"x": 1,
			"y": 3,
			"z": 4
		}, {
			"elements": ["actuallyadditions:block_giant_chest_large@0"],
			"x": 2,
			"y": 1,
			"z": 1
		}, {
			"elements": ["mysticalagriculture:growth_accelerator@0"],
			"x": 2,
			"y": 3,
			"z": 4
		}, {
			"elements": ["actuallyadditions:block_giant_chest_large@0"],
			"x": 2,
			"y": 1,
			"z": 3
		}, {
			"elements": ["extendedcrafting:trimmed@5"],
			"x": -2,
			"y": 2,
			"z": 1
		}, {
			"elements": ["extendedcrafting:storage@3"],
			"x": -1,
			"y": 4,
			"z": 2
		}, {
			"elements": ["cyclicmagic:exp_pylon@2"],
			"x": 0,
			"y": 4,
			"z": 2
		}, {
			"elements": ["extendedcrafting:storage@3"],
			"x": 1,
			"y": 4,
			"z": 2
		}, {
			"elements": ["extendedcrafting:trimmed@5"],
			"x": -2,
			"y": 2,
			"z": 3
		}
	]
}
