{
	"registryname": "seed_infuser",
	"localizedname": "Seed Infuser",
	"parts": [{
			"x": -1,
			"y": 0,
			"z": 0,
			"elements": [
				"modularmachinery:blockenergyinputhatch@7"
			]
		}, {
			"x": 4,
			"y": 8,
			"z": 4,
			"elements": [
				"modularmachinery:blockcasing@0"
			]
		}, {
			"x": 2,
			"y": 4,
			"z": 2,
			"elements": [
				"modularmachinery:blockcasing@4"
			]
		}, {
			"x": 5,
			"y": 8,
			"z": 4,
			"elements": [
				"mysticalagriculture:ingot_storage@6"
			]
		}, {
			"x": 3,
			"y": 4,
			"z": 2,
			"elements": [
				"modularmachinery:blockcasing@4"
			]
		}, {
			"x": 1,
			"y": 0,
			"z": 0,
			"elements": [
				"modularmachinery:blockinputbus@6"
			]
		}, {
			"x": -2,
			"y": 0,
			"z": 0,
			"elements": [
				"mysticalagriculture:ingot_storage@6"
			]
		}, {
			"x": -3,
			"y": 0,
			"z": 0,
			"elements": [
				"mysticalagriculture:ingot_storage@6"
			]
		}, {
			"x": 4,
			"y": 4,
			"z": 2,
			"elements": [
				"modularmachinery:blockcasing@0"
			]
		}, {
			"x": 2,
			"y": 0,
			"z": 0,
			"elements": [
				"mysticalagriculture:ingot_storage@6"
			]
		}, {
			"x": 5,
			"y": 4,
			"z": 2,
			"elements": [
				"mysticalagriculture:ingot_storage@6"
			]
		}, {
			"x": 3,
			"y": 0,
			"z": 0,
			"elements": [
				"mysticalagriculture:ingot_storage@6"
			]
		}, {
			"x": -4,
			"y": 0,
			"z": 0,
			"elements": [
				"mysticalagriculture:ingot_storage@6"
			]
		}, {
			"x": -5,
			"y": 0,
			"z": 0,
			"elements": [
				"mysticalagriculture:ingot_storage@6"
			]
		}, {
			"x": 4,
			"y": 0,
			"z": 0,
			"elements": [
				"mysticalagriculture:ingot_storage@6"
			]
		}, {
			"x": 5,
			"y": 0,
			"z": 0,
			"elements": [
				"mysticalagriculture:ingot_storage@6"
			]
		}, {
			"x": -5,
			"y": 9,
			"z": 4,
			"elements": [
				"mysticalagriculture:ingot_storage@6"
			]
		}, {
			"x": -4,
			"y": 9,
			"z": 4,
			"elements": [
				"modularmachinery:blockcasing@0"
			]
		}, {
			"x": -5,
			"y": 5,
			"z": 2,
			"elements": [
				"mysticalagriculture:ingot_storage@6"
			]
		}, {
			"x": -3,
			"y": 9,
			"z": 4,
			"elements": [
				"thermalfoundation:fluid_cryotheum@0"
			]
		}, {
			"x": -4,
			"y": 5,
			"z": 2,
			"elements": [
				"modularmachinery:blockcasing@0"
			]
		}, {
			"x": -2,
			"y": 9,
			"z": 4,
			"elements": [
				"extrautils2:compresseddirt@3"
			]
		}, {
			"x": -5,
			"y": 1,
			"z": 0,
			"elements": [
				"mysticalagriculture:ingot_storage@6"
			]
		}, {
			"x": -3,
			"y": 5,
			"z": 2,
			"elements": [
				"modularmachinery:blockcasing@4"
			]
		}, {
			"x": -1,
			"y": 9,
			"z": 4,
			"elements": [
				"extrautils2:compressedsand@1"
			]
		}, {
			"x": 0,
			"y": 9,
			"z": 4,
			"elements": [
				"extrautils2:compressedsand@1"
			]
		}, {
			"x": -4,
			"y": 1,
			"z": 0,
			"elements": [
				"xtones:zane@1"
			]
		}, {
			"x": -2,
			"y": 5,
			"z": 2,
			"elements": [
				"modularmachinery:blockcasing@4"
			]
		}, {
			"x": -3,
			"y": 1,
			"z": 0,
			"elements": [
				"xtones:zane@1"
			]
		}, {
			"x": -1,
			"y": 5,
			"z": 2,
			"elements": [
				"modularmachinery:blockcasing@4"
			]
		}, {
			"x": 1,
			"y": 9,
			"z": 4,
			"elements": [
				"extrautils2:compressedsand@1"
			]
		}, {
			"x": 2,
			"y": 9,
			"z": 4,
			"elements": [
				"extrautils2:compresseddirt@3"
			]
		}, {
			"x": 0,
			"y": 5,
			"z": 2,
			"elements": [
				"modularmachinery:blockcasing@4"
			]
		}, {
			"x": -2,
			"y": 1,
			"z": 0,
			"elements": [
				"mysticalagriculture:ingot_storage@6"
			]
		}, {
			"x": -1,
			"y": 1,
			"z": 0,
			"elements": [
				"mysticalagriculture:ingot_storage@6"
			]
		}, {
			"x": 3,
			"y": 9,
			"z": 4,
			"elements": [
				"thermalfoundation:fluid_cryotheum@0"
			]
		}, {
			"x": 1,
			"y": 5,
			"z": 2,
			"elements": [
				"modularmachinery:blockcasing@4"
			]
		}, {
			"x": 4,
			"y": 9,
			"z": 4,
			"elements": [
				"modularmachinery:blockcasing@0"
			]
		}, {
			"x": 2,
			"y": 5,
			"z": 2,
			"elements": [
				"modularmachinery:blockcasing@4"
			]
		}, {
			"x": 0,
			"y": 1,
			"z": 0,
			"elements": [
				"modularmachinery:blockfluidinputhatch@7"
			]
		}, {
			"x": 5,
			"y": 9,
			"z": 4,
			"elements": [
				"mysticalagriculture:ingot_storage@6"
			]
		}, {
			"x": 3,
			"y": 5,
			"z": 2,
			"elements": [
				"modularmachinery:blockcasing@4"
			]
		}, {
			"x": 1,
			"y": 1,
			"z": 0,
			"elements": [
				"mysticalagriculture:ingot_storage@6"
			]
		}, {
			"x": 4,
			"y": 5,
			"z": 2,
			"elements": [
				"modularmachinery:blockcasing@0"
			]
		}, {
			"x": 2,
			"y": 1,
			"z": 0,
			"elements": [
				"mysticalagriculture:ingot_storage@6"
			]
		}, {
			"x": 5,
			"y": 5,
			"z": 2,
			"elements": [
				"mysticalagriculture:ingot_storage@6"
			]
		}, {
			"x": 3,
			"y": 1,
			"z": 0,
			"elements": [
				"xtones:zane@1"
			]
		}, {
			"x": 4,
			"y": 1,
			"z": 0,
			"elements": [
				"xtones:zane@1"
			]
		}, {
			"x": 5,
			"y": 1,
			"z": 0,
			"elements": [
				"mysticalagriculture:ingot_storage@6"
			]
		}, {
			"x": -5,
			"y": 10,
			"z": 4,
			"elements": [
				"mysticalagriculture:ingot_storage@6"
			]
		}, {
			"x": -4,
			"y": 10,
			"z": 4,
			"elements": [
				"draconicevolution:infused_obsidian@0"
			]
		}, {
			"x": -5,
			"y": 6,
			"z": 2,
			"elements": [
				"mysticalagriculture:ingot_storage@6"
			]
		}, {
			"x": -3,
			"y": 10,
			"z": 4,
			"elements": [
				"draconicevolution:infused_obsidian@0"
			]
		}, {
			"x": -4,
			"y": 6,
			"z": 2,
			"elements": [
				"modularmachinery:blockcasing@0"
			]
		}, {
			"x": -2,
			"y": 10,
			"z": 4,
			"elements": [
				"draconicevolution:draconium_block@1"
			]
		}, {
			"x": -5,
			"y": 2,
			"z": 0,
			"elements": [
				"mysticalagriculture:ingot_storage@6"
			]
		}, {
			"x": -3,
			"y": 6,
			"z": 2,
			"elements": [
				"modularmachinery:blockcasing@4"
			]
		}, {
			"x": -1,
			"y": 10,
			"z": 4,
			"elements": [
				"mysticalagriculture:growth_accelerator@0"
			]
		}, {
			"x": 0,
			"y": 10,
			"z": 4,
			"elements": [
				"mysticalagriculture:growth_accelerator@0"
			]
		}, {
			"x": -4,
			"y": 2,
			"z": 0,
			"elements": [
				"xtones:zane@1"
			]
		}, {
			"x": -2,
			"y": 6,
			"z": 2,
			"elements": [
				"modularmachinery:blockcasing@4"
			]
		}, {
			"x": -3,
			"y": 2,
			"z": 0,
			"elements": [
				"xtones:zane@1"
			]
		}, {
			"x": -1,
			"y": 6,
			"z": 2,
			"elements": [
				"modularmachinery:blockcasing@4"
			]
		}, {
			"x": 1,
			"y": 10,
			"z": 4,
			"elements": [
				"mysticalagriculture:growth_accelerator@0"
			]
		}, {
			"x": 2,
			"y": 10,
			"z": 4,
			"elements": [
				"draconicevolution:draconium_block@1"
			]
		}, {
			"x": 0,
			"y": 6,
			"z": 2,
			"elements": [
				"modularmachinery:blockcasing@4"
			]
		}, {
			"x": -2,
			"y": 2,
			"z": 0,
			"elements": [
				"xtones:zane@1"
			]
		}, {
			"x": -1,
			"y": 2,
			"z": 0,
			"elements": [
				"mysticalagriculture:ingot_storage@6"
			]
		}, {
			"x": 3,
			"y": 10,
			"z": 4,
			"elements": [
				"draconicevolution:infused_obsidian@0"
			]
		}, {
			"x": 1,
			"y": 6,
			"z": 2,
			"elements": [
				"modularmachinery:blockcasing@4"
			]
		}, {
			"x": 4,
			"y": 10,
			"z": 4,
			"elements": [
				"draconicevolution:infused_obsidian@0"
			]
		}, {
			"x": 2,
			"y": 6,
			"z": 2,
			"elements": [
				"modularmachinery:blockcasing@4"
			]
		}, {
			"x": 0,
			"y": 2,
			"z": 0,
			"elements": [
				"modularmachinery:blockoutputbus@6"
			]
		}, {
			"x": 5,
			"y": 10,
			"z": 4,
			"elements": [
				"mysticalagriculture:ingot_storage@6"
			]
		}, {
			"x": 3,
			"y": 6,
			"z": 2,
			"elements": [
				"modularmachinery:blockcasing@4"
			]
		}, {
			"x": 1,
			"y": 2,
			"z": 0,
			"elements": [
				"mysticalagriculture:ingot_storage@6"
			]
		}, {
			"x": 4,
			"y": 6,
			"z": 2,
			"elements": [
				"modularmachinery:blockcasing@0"
			]
		}, {
			"x": 2,
			"y": 2,
			"z": 0,
			"elements": [
				"xtones:zane@1"
			]
		}, {
			"x": 5,
			"y": 6,
			"z": 2,
			"elements": [
				"mysticalagriculture:ingot_storage@6"
			]
		}, {
			"x": 3,
			"y": 2,
			"z": 0,
			"elements": [
				"xtones:zane@1"
			]
		}, {
			"x": 4,
			"y": 2,
			"z": 0,
			"elements": [
				"xtones:zane@1"
			]
		}, {
			"x": 5,
			"y": 2,
			"z": 0,
			"elements": [
				"mysticalagriculture:ingot_storage@6"
			]
		}, {
			"x": -5,
			"y": 11,
			"z": 4,
			"elements": [
				"extrautils2:cursedearth@0"
			]
		}, {
			"x": -4,
			"y": 11,
			"z": 4,
			"elements": [
				"extrautils2:cursedearth@0"
			]
		}, {
			"x": -5,
			"y": 7,
			"z": 2,
			"elements": [
				"xtones:zane@1"
			]
		}, {
			"x": -3,
			"y": 11,
			"z": 4,
			"elements": [
				"extrautils2:cursedearth@0"
			]
		}, {
			"x": -4,
			"y": 7,
			"z": 2,
			"elements": [
				"modularmachinery:blockcasing@0"
			]
		}, {
			"x": -2,
			"y": 11,
			"z": 4,
			"elements": [
				"extrautils2:cursedearth@0"
			]
		}, {
			"x": -5,
			"y": 3,
			"z": 0,
			"elements": [
				"mysticalagriculture:ingot_storage@6"
			]
		}, {
			"x": -3,
			"y": 7,
			"z": 2,
			"elements": [
				"modularmachinery:blockcasing@4"
			]
		}, {
			"x": -1,
			"y": 11,
			"z": 4,
			"elements": [
				"extrautils2:cursedearth@0"
			]
		}, {
			"x": 0,
			"y": 11,
			"z": 4,
			"elements": [
				"extrautils2:cursedearth@0"
			]
		}, {
			"x": -4,
			"y": 3,
			"z": 0,
			"elements": [
				"mysticalagriculture:ingot_storage@6"
			]
		}, {
			"x": -2,
			"y": 7,
			"z": 2,
			"elements": [
				"modularmachinery:blockcasing@4"
			]
		}, {
			"x": -3,
			"y": 3,
			"z": 0,
			"elements": [
				"xtones:zane@1"
			]
		}, {
			"x": -1,
			"y": 7,
			"z": 2,
			"elements": [
				"modularmachinery:blockcasing@4"
			]
		}, {
			"x": 1,
			"y": 11,
			"z": 4,
			"elements": [
				"extrautils2:cursedearth@0"
			]
		}, {
			"x": 2,
			"y": 11,
			"z": 4,
			"elements": [
				"extrautils2:cursedearth@0"
			]
		}, {
			"x": 0,
			"y": 7,
			"z": 2,
			"elements": [
				"modularmachinery:blockcasing@4"
			]
		}, {
			"x": -2,
			"y": 3,
			"z": 0,
			"elements": [
				"xtones:zane@1"
			]
		}, {
			"x": -1,
			"y": 3,
			"z": 0,
			"elements": [
				"xtones:zane@1"
			]
		}, {
			"x": 3,
			"y": 11,
			"z": 4,
			"elements": [
				"extrautils2:cursedearth@0"
			]
		}, {
			"x": 1,
			"y": 7,
			"z": 2,
			"elements": [
				"modularmachinery:blockcasing@4"
			]
		}, {
			"x": 4,
			"y": 11,
			"z": 4,
			"elements": [
				"extrautils2:cursedearth@0"
			]
		}, {
			"x": 2,
			"y": 7,
			"z": 2,
			"elements": [
				"modularmachinery:blockcasing@4"
			]
		}, {
			"x": 0,
			"y": 3,
			"z": 0,
			"elements": [
				"mysticalagriculture:ingot_storage@6"
			]
		}, {
			"x": 5,
			"y": 11,
			"z": 4,
			"elements": [
				"extrautils2:cursedearth@0"
			]
		}, {
			"x": 3,
			"y": 7,
			"z": 2,
			"elements": [
				"modularmachinery:blockcasing@4"
			]
		}, {
			"x": 1,
			"y": 3,
			"z": 0,
			"elements": [
				"xtones:zane@1"
			]
		}, {
			"x": 4,
			"y": 7,
			"z": 2,
			"elements": [
				"modularmachinery:blockcasing@0"
			]
		}, {
			"x": 2,
			"y": 3,
			"z": 0,
			"elements": [
				"xtones:zane@1"
			]
		}, {
			"x": 5,
			"y": 7,
			"z": 2,
			"elements": [
				"xtones:zane@1"
			]
		}, {
			"x": 3,
			"y": 3,
			"z": 0,
			"elements": [
				"xtones:zane@1"
			]
		}, {
			"x": 4,
			"y": 3,
			"z": 0,
			"elements": [
				"mysticalagriculture:ingot_storage@6"
			]
		}, {
			"x": 5,
			"y": 3,
			"z": 0,
			"elements": [
				"mysticalagriculture:ingot_storage@6"
			]
		}, {
			"x": -5,
			"y": 8,
			"z": 2,
			"elements": [
				"xtones:zane@1"
			]
		}, {
			"x": -4,
			"y": 8,
			"z": 2,
			"elements": [
				"modularmachinery:blockcasing@0"
			]
		}, {
			"x": -5,
			"y": 4,
			"z": 0,
			"elements": [
				"mysticalagriculture:ingot_storage@6"
			]
		}, {
			"x": -3,
			"y": 8,
			"z": 2,
			"elements": [
				"modularmachinery:blockcasing@4"
			]
		}, {
			"x": -4,
			"y": 4,
			"z": 0,
			"elements": [
				"mysticalagriculture:ingot_storage@6"
			]
		}, {
			"x": -2,
			"y": 8,
			"z": 2,
			"elements": [
				"modularmachinery:blockcasing@4"
			]
		}, {
			"x": -3,
			"y": 4,
			"z": 0,
			"elements": [
				"mysticalagriculture:ingot_storage@6"
			]
		}, {
			"x": -1,
			"y": 8,
			"z": 2,
			"elements": [
				"modularmachinery:blockcasing@4"
			]
		}, {
			"x": 0,
			"y": 8,
			"z": 2,
			"elements": [
				"modularmachinery:blockcasing@4"
			]
		}, {
			"x": -2,
			"y": 4,
			"z": 0,
			"elements": [
				"xtones:zane@1"
			]
		}, {
			"x": -1,
			"y": 4,
			"z": 0,
			"elements": [
				"xtones:zane@1"
			]
		}, {
			"x": 2,
			"y": 8,
			"z": 2,
			"elements": [
				"modularmachinery:blockcasing@4"
			]
		}, {
			"x": 0,
			"y": 4,
			"z": 0,
			"elements": [
				"xtones:zane@1"
			]
		}, {
			"x": 3,
			"y": 8,
			"z": 2,
			"elements": [
				"modularmachinery:blockcasing@4"
			]
		}, {
			"x": 1,
			"y": 4,
			"z": 0,
			"elements": [
				"xtones:zane@1"
			]
		}, {
			"x": 4,
			"y": 8,
			"z": 2,
			"elements": [
				"modularmachinery:blockcasing@0"
			]
		}, {
			"x": 2,
			"y": 4,
			"z": 0,
			"elements": [
				"xtones:zane@1"
			]
		}, {
			"x": 5,
			"y": 8,
			"z": 2,
			"elements": [
				"xtones:zane@1"
			]
		}, {
			"x": 3,
			"y": 4,
			"z": 0,
			"elements": [
				"mysticalagriculture:ingot_storage@6"
			]
		}, {
			"x": 4,
			"y": 4,
			"z": 0,
			"elements": [
				"mysticalagriculture:ingot_storage@6"
			]
		}, {
			"x": 5,
			"y": 4,
			"z": 0,
			"elements": [
				"mysticalagriculture:ingot_storage@6"
			]
		}, {
			"x": -5,
			"y": 9,
			"z": 2,
			"elements": [
				"xtones:zane@1"
			]
		}, {
			"x": -4,
			"y": 9,
			"z": 2,
			"elements": [
				"modularmachinery:blockcasing@0"
			]
		}, {
			"x": -5,
			"y": 5,
			"z": 0,
			"elements": [
				"mysticalagriculture:ingot_storage@6"
			]
		}, {
			"x": -3,
			"y": 9,
			"z": 2,
			"elements": [
				"thermalfoundation:fluid_cryotheum@0"
			]
		}, {
			"x": -4,
			"y": 5,
			"z": 0,
			"elements": [
				"mysticalagriculture:ingot_storage@6"
			]
		}, {
			"x": -2,
			"y": 9,
			"z": 2,
			"elements": [
				"thermalfoundation:fluid_cryotheum@0"
			]
		}, {
			"x": -3,
			"y": 5,
			"z": 0,
			"elements": [
				"mysticalagriculture:ingot_storage@6"
			]
		}, {
			"x": -1,
			"y": 9,
			"z": 2,
			"elements": [
				"thermalfoundation:fluid_cryotheum@0"
			]
		}, {
			"x": 0,
			"y": 9,
			"z": 2,
			"elements": [
				"thermalfoundation:fluid_cryotheum@0"
			]
		}, {
			"x": -2,
			"y": 5,
			"z": 0,
			"elements": [
				"mysticalagriculture:ingot_storage@6"
			]
		}, {
			"x": -1,
			"y": 5,
			"z": 0,
			"elements": [
				"xtones:zane@1"
			]
		}, {
			"x": 1,
			"y": 9,
			"z": 2,
			"elements": [
				"thermalfoundation:fluid_cryotheum@0"
			]
		}, {
			"x": 2,
			"y": 9,
			"z": 2,
			"elements": [
				"thermalfoundation:fluid_cryotheum@0"
			]
		}, {
			"x": 0,
			"y": 5,
			"z": 0,
			"elements": [
				"xtones:zane@1"
			]
		}, {
			"x": 3,
			"y": 9,
			"z": 2,
			"elements": [
				"thermalfoundation:fluid_cryotheum@0"
			]
		}, {
			"x": 1,
			"y": 5,
			"z": 0,
			"elements": [
				"xtones:zane@1"
			]
		}, {
			"x": 4,
			"y": 9,
			"z": 2,
			"elements": [
				"modularmachinery:blockcasing@0"
			]
		}, {
			"x": 2,
			"y": 5,
			"z": 0,
			"elements": [
				"mysticalagriculture:ingot_storage@6"
			]
		}, {
			"x": 5,
			"y": 9,
			"z": 2,
			"elements": [
				"xtones:zane@1"
			]
		}, {
			"x": 3,
			"y": 5,
			"z": 0,
			"elements": [
				"mysticalagriculture:ingot_storage@6"
			]
		}, {
			"x": 4,
			"y": 5,
			"z": 0,
			"elements": [
				"mysticalagriculture:ingot_storage@6"
			]
		}, {
			"x": 5,
			"y": 5,
			"z": 0,
			"elements": [
				"mysticalagriculture:ingot_storage@6"
			]
		}, {
			"x": -5,
			"y": 10,
			"z": 2,
			"elements": [
				"mysticalagriculture:ingot_storage@6"
			]
		}, {
			"x": -4,
			"y": 10,
			"z": 2,
			"elements": [
				"draconicevolution:infused_obsidian@0"
			]
		}, {
			"x": -5,
			"y": 6,
			"z": 0,
			"elements": [
				"mysticalagriculture:ingot_storage@6"
			]
		}, {
			"x": -3,
			"y": 10,
			"z": 2,
			"elements": [
				"draconicevolution:infused_obsidian@0"
			]
		}, {
			"x": -4,
			"y": 6,
			"z": 0,
			"elements": [
				"mysticalagriculture:ingot_storage@6"
			]
		}, {
			"x": -2,
			"y": 10,
			"z": 2,
			"elements": [
				"draconicevolution:infused_obsidian@0"
			]
		}, {
			"x": -3,
			"y": 6,
			"z": 0,
			"elements": [
				"mysticalagriculture:ingot_storage@6"
			]
		}, {
			"x": -1,
			"y": 10,
			"z": 2,
			"elements": [
				"draconicevolution:infused_obsidian@0"
			]
		}, {
			"x": 0,
			"y": 10,
			"z": 2,
			"elements": [
				"draconicevolution:infused_obsidian@0"
			]
		}, {
			"x": -2,
			"y": 6,
			"z": 0,
			"elements": [
				"xtones:zane@1"
			]
		}, {
			"x": -1,
			"y": 6,
			"z": 0,
			"elements": [
				"xtones:zane@1"
			]
		}, {
			"x": 1,
			"y": 10,
			"z": 2,
			"elements": [
				"draconicevolution:infused_obsidian@0"
			]
		}, {
			"x": 2,
			"y": 10,
			"z": 2,
			"elements": [
				"draconicevolution:infused_obsidian@0"
			]
		}, {
			"x": 0,
			"y": 6,
			"z": 0,
			"elements": [
				"xtones:zane@1"
			]
		}, {
			"x": 3,
			"y": 10,
			"z": 2,
			"elements": [
				"draconicevolution:infused_obsidian@0"
			]
		}, {
			"x": 1,
			"y": 6,
			"z": 0,
			"elements": [
				"xtones:zane@1"
			]
		}, {
			"x": 4,
			"y": 10,
			"z": 2,
			"elements": [
				"draconicevolution:infused_obsidian@0"
			]
		}, {
			"x": 2,
			"y": 6,
			"z": 0,
			"elements": [
				"xtones:zane@1"
			]
		}, {
			"x": 5,
			"y": 10,
			"z": 2,
			"elements": [
				"mysticalagriculture:ingot_storage@6"
			]
		}, {
			"x": 3,
			"y": 6,
			"z": 0,
			"elements": [
				"mysticalagriculture:ingot_storage@6"
			]
		}, {
			"x": 4,
			"y": 6,
			"z": 0,
			"elements": [
				"mysticalagriculture:ingot_storage@6"
			]
		}, {
			"x": 5,
			"y": 6,
			"z": 0,
			"elements": [
				"mysticalagriculture:ingot_storage@6"
			]
		}, {
			"x": -5,
			"y": 11,
			"z": 2,
			"elements": [
				"extrautils2:cursedearth@0"
			]
		}, {
			"x": -4,
			"y": 11,
			"z": 2,
			"elements": [
				"extrautils2:cursedearth@0"
			]
		}, {
			"x": -5,
			"y": 7,
			"z": 0,
			"elements": [
				"mysticalagriculture:ingot_storage@6"
			]
		}, {
			"x": -3,
			"y": 11,
			"z": 2,
			"elements": [
				"extrautils2:cursedearth@0"
			]
		}, {
			"x": -4,
			"y": 7,
			"z": 0,
			"elements": [
				"mysticalagriculture:ingot_storage@6"
			]
		}, {
			"x": -2,
			"y": 11,
			"z": 2,
			"elements": [
				"extrautils2:cursedearth@0"
			]
		}, {
			"x": -3,
			"y": 7,
			"z": 0,
			"elements": [
				"xtones:zane@1"
			]
		}, {
			"x": -1,
			"y": 11,
			"z": 2,
			"elements": [
				"extrautils2:cursedearth@0"
			]
		}, {
			"x": 0,
			"y": 11,
			"z": 2,
			"elements": [
				"extrautils2:cursedearth@0"
			]
		}, {
			"x": -2,
			"y": 7,
			"z": 0,
			"elements": [
				"xtones:zane@1"
			]
		}, {
			"x": -1,
			"y": 7,
			"z": 0,
			"elements": [
				"xtones:zane@1"
			]
		}, {
			"x": 1,
			"y": 11,
			"z": 2,
			"elements": [
				"extrautils2:cursedearth@0"
			]
		}, {
			"x": 2,
			"y": 11,
			"z": 2,
			"elements": [
				"extrautils2:cursedearth@0"
			]
		}, {
			"x": 0,
			"y": 7,
			"z": 0,
			"elements": [
				"mysticalagriculture:ingot_storage@6"
			]
		}, {
			"x": 3,
			"y": 11,
			"z": 2,
			"elements": [
				"extrautils2:cursedearth@0"
			]
		}, {
			"x": 1,
			"y": 7,
			"z": 0,
			"elements": [
				"xtones:zane@1"
			]
		}, {
			"x": 4,
			"y": 11,
			"z": 2,
			"elements": [
				"extrautils2:cursedearth@0"
			]
		}, {
			"x": 2,
			"y": 7,
			"z": 0,
			"elements": [
				"xtones:zane@1"
			]
		}, {
			"x": 5,
			"y": 11,
			"z": 2,
			"elements": [
				"extrautils2:cursedearth@0"
			]
		}, {
			"x": 3,
			"y": 7,
			"z": 0,
			"elements": [
				"xtones:zane@1"
			]
		}, {
			"x": 4,
			"y": 7,
			"z": 0,
			"elements": [
				"mysticalagriculture:ingot_storage@6"
			]
		}, {
			"x": 5,
			"y": 7,
			"z": 0,
			"elements": [
				"mysticalagriculture:ingot_storage@6"
			]
		}, {
			"x": -5,
			"y": 8,
			"z": 0,
			"elements": [
				"mysticalagriculture:ingot_storage@6"
			]
		}, {
			"x": -4,
			"y": 8,
			"z": 0,
			"elements": [
				"xtones:zane@1"
			]
		}, {
			"x": -3,
			"y": 8,
			"z": 0,
			"elements": [
				"xtones:zane@1"
			]
		}, {
			"x": -2,
			"y": 8,
			"z": 0,
			"elements": [
				"xtones:zane@1"
			]
		}, {
			"x": -1,
			"y": 8,
			"z": 0,
			"elements": [
				"mysticalagriculture:ingot_storage@6"
			]
		}, {
			"x": 0,
			"y": 8,
			"z": 0,
			"elements": [
				"mysticalagriculture:ingot_storage@6"
			]
		}, {
			"x": 1,
			"y": 8,
			"z": 0,
			"elements": [
				"mysticalagriculture:ingot_storage@6"
			]
		}, {
			"x": 2,
			"y": 8,
			"z": 0,
			"elements": [
				"xtones:zane@1"
			]
		}, {
			"x": 3,
			"y": 8,
			"z": 0,
			"elements": [
				"xtones:zane@1"
			]
		}, {
			"x": 4,
			"y": 8,
			"z": 0,
			"elements": [
				"xtones:zane@1"
			]
		}, {
			"x": 5,
			"y": 8,
			"z": 0,
			"elements": [
				"mysticalagriculture:ingot_storage@6"
			]
		}, {
			"x": -5,
			"y": 9,
			"z": 0,
			"elements": [
				"mysticalagriculture:ingot_storage@6"
			]
		}, {
			"x": -4,
			"y": 9,
			"z": 0,
			"elements": [
				"xtones:zane@1"
			]
		}, {
			"x": -3,
			"y": 9,
			"z": 0,
			"elements": [
				"xtones:zane@1"
			]
		}, {
			"x": -2,
			"y": 9,
			"z": 0,
			"elements": [
				"mysticalagriculture:ingot_storage@6"
			]
		}, {
			"x": -1,
			"y": 9,
			"z": 0,
			"elements": [
				"mysticalagriculture:ingot_storage@6"
			]
		}, {
			"x": 0,
			"y": 9,
			"z": 0,
			"elements": [
				"mysticalagriculture:ingot_storage@6"
			]
		}, {
			"x": 1,
			"y": 9,
			"z": 0,
			"elements": [
				"mysticalagriculture:ingot_storage@6"
			]
		}, {
			"x": 2,
			"y": 9,
			"z": 0,
			"elements": [
				"mysticalagriculture:ingot_storage@6"
			]
		}, {
			"x": 3,
			"y": 9,
			"z": 0,
			"elements": [
				"xtones:zane@1"
			]
		}, {
			"x": 4,
			"y": 9,
			"z": 0,
			"elements": [
				"xtones:zane@1"
			]
		}, {
			"x": 5,
			"y": 9,
			"z": 0,
			"elements": [
				"mysticalagriculture:ingot_storage@6"
			]
		}, {
			"x": -5,
			"y": 10,
			"z": 0,
			"elements": [
				"mysticalagriculture:ingot_storage@6"
			]
		}, {
			"x": -4,
			"y": 10,
			"z": 0,
			"elements": [
				"mysticalagriculture:ingot_storage@6"
			]
		}, {
			"x": -3,
			"y": 10,
			"z": 0,
			"elements": [
				"mysticalagriculture:ingot_storage@6"
			]
		}, {
			"x": -2,
			"y": 10,
			"z": 0,
			"elements": [
				"mysticalagriculture:ingot_storage@6"
			]
		}, {
			"x": -1,
			"y": 10,
			"z": 0,
			"elements": [
				"mysticalagriculture:ingot_storage@6"
			]
		}, {
			"x": 0,
			"y": 10,
			"z": 0,
			"elements": [
				"mysticalagriculture:ingot_storage@6"
			]
		}, {
			"x": 1,
			"y": 10,
			"z": 0,
			"elements": [
				"mysticalagriculture:ingot_storage@6"
			]
		}, {
			"x": 2,
			"y": 10,
			"z": 0,
			"elements": [
				"mysticalagriculture:ingot_storage@6"
			]
		}, {
			"x": 3,
			"y": 10,
			"z": 0,
			"elements": [
				"mysticalagriculture:ingot_storage@6"
			]
		}, {
			"x": 4,
			"y": 10,
			"z": 0,
			"elements": [
				"mysticalagriculture:ingot_storage@6"
			]
		}, {
			"x": 5,
			"y": 10,
			"z": 0,
			"elements": [
				"mysticalagriculture:ingot_storage@6"
			]
		}, {
			"x": -5,
			"y": 11,
			"z": 0,
			"elements": [
				"extrautils2:cursedearth@0"
			]
		}, {
			"x": -4,
			"y": 11,
			"z": 0,
			"elements": [
				"extrautils2:cursedearth@0"
			]
		}, {
			"x": -3,
			"y": 11,
			"z": 0,
			"elements": [
				"extrautils2:cursedearth@0"
			]
		}, {
			"x": -2,
			"y": 11,
			"z": 0,
			"elements": [
				"extrautils2:cursedearth@0"
			]
		}, {
			"x": -1,
			"y": 11,
			"z": 0,
			"elements": [
				"extrautils2:cursedearth@0"
			]
		}, {
			"x": 0,
			"y": 11,
			"z": 0,
			"elements": [
				"extrautils2:cursedearth@0"
			]
		}, {
			"x": 1,
			"y": 11,
			"z": 0,
			"elements": [
				"extrautils2:cursedearth@0"
			]
		}, {
			"x": 2,
			"y": 11,
			"z": 0,
			"elements": [
				"extrautils2:cursedearth@0"
			]
		}, {
			"x": 3,
			"y": 11,
			"z": 0,
			"elements": [
				"extrautils2:cursedearth@0"
			]
		}, {
			"x": 4,
			"y": 11,
			"z": 0,
			"elements": [
				"extrautils2:cursedearth@0"
			]
		}, {
			"x": 5,
			"y": 11,
			"z": 0,
			"elements": [
				"extrautils2:cursedearth@0"
			]
		}, {
			"x": -5,
			"y": 0,
			"z": 9,
			"elements": [
				"mysticalagriculture:ingot_storage@6"
			]
		}, {
			"x": -4,
			"y": 0,
			"z": 9,
			"elements": [
				"modularmachinery:blockcasing@0"
			]
		}, {
			"x": -3,
			"y": 0,
			"z": 9,
			"elements": [
				"modularmachinery:blockcasing@0"
			]
		}, {
			"x": -2,
			"y": 0,
			"z": 9,
			"elements": [
				"modularmachinery:blockcasing@0"
			]
		}, {
			"x": -1,
			"y": 0,
			"z": 9,
			"elements": [
				"modularmachinery:blockcasing@0"
			]
		}, {
			"x": 0,
			"y": 0,
			"z": 9,
			"elements": [
				"modularmachinery:blockcasing@0"
			]
		}, {
			"x": 1,
			"y": 0,
			"z": 9,
			"elements": [
				"modularmachinery:blockcasing@0"
			]
		}, {
			"x": 2,
			"y": 0,
			"z": 9,
			"elements": [
				"modularmachinery:blockcasing@0"
			]
		}, {
			"x": 3,
			"y": 0,
			"z": 9,
			"elements": [
				"modularmachinery:blockcasing@0"
			]
		}, {
			"x": 4,
			"y": 0,
			"z": 9,
			"elements": [
				"modularmachinery:blockcasing@0"
			]
		}, {
			"x": 5,
			"y": 0,
			"z": 9,
			"elements": [
				"mysticalagriculture:ingot_storage@6"
			]
		}, {
			"x": -5,
			"y": 1,
			"z": 9,
			"elements": [
				"xtones:zane@1"
			]
		}, {
			"x": -4,
			"y": 1,
			"z": 9,
			"elements": [
				"modularmachinery:blockcasing@0"
			]
		}, {
			"x": -3,
			"y": 1,
			"z": 9,
			"elements": [
				"modularmachinery:blockcasing@0"
			]
		}, {
			"x": -2,
			"y": 1,
			"z": 9,
			"elements": [
				"modularmachinery:blockcasing@0"
			]
		}, {
			"x": -1,
			"y": 1,
			"z": 9,
			"elements": [
				"modularmachinery:blockcasing@0"
			]
		}, {
			"x": 0,
			"y": 1,
			"z": 9,
			"elements": [
				"modularmachinery:blockcasing@0"
			]
		}, {
			"x": 1,
			"y": 1,
			"z": 9,
			"elements": [
				"modularmachinery:blockcasing@0"
			]
		}, {
			"x": 2,
			"y": 1,
			"z": 9,
			"elements": [
				"modularmachinery:blockcasing@0"
			]
		}, {
			"x": 3,
			"y": 1,
			"z": 9,
			"elements": [
				"modularmachinery:blockcasing@0"
			]
		}, {
			"x": 4,
			"y": 1,
			"z": 9,
			"elements": [
				"modularmachinery:blockcasing@0"
			]
		}, {
			"x": 5,
			"y": 1,
			"z": 9,
			"elements": [
				"xtones:zane@1"
			]
		}, {
			"x": -5,
			"y": 2,
			"z": 9,
			"elements": [
				"xtones:zane@1"
			]
		}, {
			"x": -4,
			"y": 2,
			"z": 9,
			"elements": [
				"modularmachinery:blockcasing@0"
			]
		}, {
			"x": -3,
			"y": 2,
			"z": 9,
			"elements": [
				"modularmachinery:blockcasing@0"
			]
		}, {
			"x": -2,
			"y": 2,
			"z": 9,
			"elements": [
				"modularmachinery:blockcasing@0"
			]
		}, {
			"x": -1,
			"y": 2,
			"z": 9,
			"elements": [
				"modularmachinery:blockcasing@0"
			]
		}, {
			"x": 0,
			"y": 2,
			"z": 9,
			"elements": [
				"modularmachinery:blockcasing@0"
			]
		}, {
			"x": 1,
			"y": 2,
			"z": 9,
			"elements": [
				"modularmachinery:blockcasing@0"
			]
		}, {
			"x": 2,
			"y": 2,
			"z": 9,
			"elements": [
				"modularmachinery:blockcasing@0"
			]
		}, {
			"x": 3,
			"y": 2,
			"z": 9,
			"elements": [
				"modularmachinery:blockcasing@0"
			]
		}, {
			"x": 4,
			"y": 2,
			"z": 9,
			"elements": [
				"modularmachinery:blockcasing@0"
			]
		}, {
			"x": 5,
			"y": 2,
			"z": 9,
			"elements": [
				"xtones:zane@1"
			]
		}, {
			"x": -5,
			"y": 3,
			"z": 9,
			"elements": [
				"mysticalagriculture:ingot_storage@6"
			]
		}, {
			"x": -4,
			"y": 3,
			"z": 9,
			"elements": [
				"modularmachinery:blockcasing@0"
			]
		}, {
			"x": -3,
			"y": 3,
			"z": 9,
			"elements": [
				"modularmachinery:blockcasing@0"
			]
		}, {
			"x": -2,
			"y": 3,
			"z": 9,
			"elements": [
				"modularmachinery:blockcasing@0"
			]
		}, {
			"x": -1,
			"y": 3,
			"z": 9,
			"elements": [
				"modularmachinery:blockcasing@0"
			]
		}, {
			"x": 0,
			"y": 3,
			"z": 9,
			"elements": [
				"modularmachinery:blockcasing@0"
			]
		}, {
			"x": 1,
			"y": 3,
			"z": 9,
			"elements": [
				"modularmachinery:blockcasing@0"
			]
		}, {
			"x": 2,
			"y": 3,
			"z": 9,
			"elements": [
				"modularmachinery:blockcasing@0"
			]
		}, {
			"x": 3,
			"y": 3,
			"z": 9,
			"elements": [
				"modularmachinery:blockcasing@0"
			]
		}, {
			"x": 4,
			"y": 3,
			"z": 9,
			"elements": [
				"modularmachinery:blockcasing@0"
			]
		}, {
			"x": 5,
			"y": 3,
			"z": 9,
			"elements": [
				"mysticalagriculture:ingot_storage@6"
			]
		}, {
			"x": -5,
			"y": 4,
			"z": 9,
			"elements": [
				"mysticalagriculture:ingot_storage@6"
			]
		}, {
			"x": -4,
			"y": 4,
			"z": 9,
			"elements": [
				"modularmachinery:blockcasing@0"
			]
		}, {
			"x": -5,
			"y": 0,
			"z": 7,
			"elements": [
				"mysticalagriculture:ingot_storage@6"
			]
		}, {
			"x": -3,
			"y": 4,
			"z": 9,
			"elements": [
				"modularmachinery:blockcasing@0"
			]
		}, {
			"x": -4,
			"y": 0,
			"z": 7,
			"elements": [
				"modularmachinery:blockcasing@0"
			]
		}, {
			"x": -2,
			"y": 4,
			"z": 9,
			"elements": [
				"modularmachinery:blockcasing@0"
			]
		}, {
			"x": -3,
			"y": 0,
			"z": 7,
			"elements": [
				"modularmachinery:blockcasing@4"
			]
		}, {
			"x": -1,
			"y": 4,
			"z": 9,
			"elements": [
				"modularmachinery:blockcasing@0"
			]
		}, {
			"x": 0,
			"y": 4,
			"z": 9,
			"elements": [
				"modularmachinery:blockcasing@0"
			]
		}, {
			"x": -2,
			"y": 0,
			"z": 7,
			"elements": [
				"modularmachinery:blockcasing@2"
			]
		}, {
			"x": -1,
			"y": 0,
			"z": 7,
			"elements": [
				"modularmachinery:blockcasing@2"
			]
		}, {
			"x": 1,
			"y": 4,
			"z": 9,
			"elements": [
				"modularmachinery:blockcasing@0"
			]
		}, {
			"x": 0,
			"y": 0,
			"z": 7,
			"elements": [
				"modularmachinery:blockcasing@2"
			]
		}, {
			"x": 2,
			"y": 4,
			"z": 9,
			"elements": [
				"modularmachinery:blockcasing@0"
			]
		}, {
			"x": 3,
			"y": 4,
			"z": 9,
			"elements": [
				"modularmachinery:blockcasing@0"
			]
		}, {
			"x": 1,
			"y": 0,
			"z": 7,
			"elements": [
				"modularmachinery:blockcasing@2"
			]
		}, {
			"x": 4,
			"y": 4,
			"z": 9,
			"elements": [
				"modularmachinery:blockcasing@0"
			]
		}, {
			"x": 2,
			"y": 0,
			"z": 7,
			"elements": [
				"modularmachinery:blockcasing@2"
			]
		}, {
			"x": 5,
			"y": 4,
			"z": 9,
			"elements": [
				"mysticalagriculture:ingot_storage@6"
			]
		}, {
			"x": 3,
			"y": 0,
			"z": 7,
			"elements": [
				"modularmachinery:blockcasing@4"
			]
		}, {
			"x": 4,
			"y": 0,
			"z": 7,
			"elements": [
				"modularmachinery:blockcasing@0"
			]
		}, {
			"x": 5,
			"y": 0,
			"z": 7,
			"elements": [
				"mysticalagriculture:ingot_storage@6"
			]
		}, {
			"x": -5,
			"y": 5,
			"z": 9,
			"elements": [
				"mysticalagriculture:ingot_storage@6"
			]
		}, {
			"x": -4,
			"y": 5,
			"z": 9,
			"elements": [
				"modularmachinery:blockcasing@0"
			]
		}, {
			"x": -5,
			"y": 1,
			"z": 7,
			"elements": [
				"mysticalagriculture:ingot_storage@6"
			]
		}, {
			"x": -3,
			"y": 5,
			"z": 9,
			"elements": [
				"modularmachinery:blockcasing@0"
			]
		}, {
			"x": -4,
			"y": 1,
			"z": 7,
			"elements": [
				"modularmachinery:blockcasing@0"
			]
		}, {
			"x": -2,
			"y": 5,
			"z": 9,
			"elements": [
				"modularmachinery:blockcasing@0"
			]
		}, {
			"x": -3,
			"y": 1,
			"z": 7,
			"elements": [
				"modularmachinery:blockcasing@4"
			]
		}, {
			"x": -1,
			"y": 5,
			"z": 9,
			"elements": [
				"modularmachinery:blockcasing@0"
			]
		}, {
			"x": 0,
			"y": 5,
			"z": 9,
			"elements": [
				"modularmachinery:blockcasing@0"
			]
		}, {
			"x": -2,
			"y": 1,
			"z": 7,
			"elements": [
				"modularmachinery:blockcasing@2"
			]
		}, {
			"x": -1,
			"y": 1,
			"z": 7,
			"elements": [
				"modularmachinery:blockcasing@2"
			]
		}, {
			"x": 1,
			"y": 5,
			"z": 9,
			"elements": [
				"modularmachinery:blockcasing@0"
			]
		}, {
			"x": 2,
			"y": 5,
			"z": 9,
			"elements": [
				"modularmachinery:blockcasing@0"
			]
		}, {
			"x": 0,
			"y": 1,
			"z": 7,
			"elements": [
				"modularmachinery:blockcasing@2"
			]
		}, {
			"x": 3,
			"y": 5,
			"z": 9,
			"elements": [
				"modularmachinery:blockcasing@0"
			]
		}, {
			"x": 1,
			"y": 1,
			"z": 7,
			"elements": [
				"modularmachinery:blockcasing@2"
			]
		}, {
			"x": 4,
			"y": 5,
			"z": 9,
			"elements": [
				"modularmachinery:blockcasing@0"
			]
		}, {
			"x": 2,
			"y": 1,
			"z": 7,
			"elements": [
				"modularmachinery:blockcasing@2"
			]
		}, {
			"x": 5,
			"y": 5,
			"z": 9,
			"elements": [
				"mysticalagriculture:ingot_storage@6"
			]
		}, {
			"x": 3,
			"y": 1,
			"z": 7,
			"elements": [
				"modularmachinery:blockcasing@4"
			]
		}, {
			"x": 4,
			"y": 1,
			"z": 7,
			"elements": [
				"modularmachinery:blockcasing@0"
			]
		}, {
			"x": 5,
			"y": 1,
			"z": 7,
			"elements": [
				"mysticalagriculture:ingot_storage@6"
			]
		}, {
			"x": -5,
			"y": 6,
			"z": 9,
			"elements": [
				"mysticalagriculture:ingot_storage@6"
			]
		}, {
			"x": -4,
			"y": 6,
			"z": 9,
			"elements": [
				"modularmachinery:blockcasing@0"
			]
		}, {
			"x": -5,
			"y": 2,
			"z": 7,
			"elements": [
				"xtones:zane@1"
			]
		}, {
			"x": -3,
			"y": 6,
			"z": 9,
			"elements": [
				"modularmachinery:blockcasing@0"
			]
		}, {
			"x": -4,
			"y": 2,
			"z": 7,
			"elements": [
				"modularmachinery:blockcasing@0"
			]
		}, {
			"x": -2,
			"y": 6,
			"z": 9,
			"elements": [
				"modularmachinery:blockcasing@0"
			]
		}, {
			"x": -3,
			"y": 2,
			"z": 7,
			"elements": [
				"modularmachinery:blockcasing@4"
			]
		}, {
			"x": -1,
			"y": 6,
			"z": 9,
			"elements": [
				"modularmachinery:blockcasing@0"
			]
		}, {
			"x": 0,
			"y": 6,
			"z": 9,
			"elements": [
				"modularmachinery:blockcasing@0"
			]
		}, {
			"x": -2,
			"y": 2,
			"z": 7,
			"elements": [
				"modularmachinery:blockcasing@2"
			]
		}, {
			"x": -1,
			"y": 2,
			"z": 7,
			"elements": [
				"modularmachinery:blockcasing@2"
			]
		}, {
			"x": 1,
			"y": 6,
			"z": 9,
			"elements": [
				"modularmachinery:blockcasing@0"
			]
		}, {
			"x": 2,
			"y": 6,
			"z": 9,
			"elements": [
				"modularmachinery:blockcasing@0"
			]
		}, {
			"x": 0,
			"y": 2,
			"z": 7,
			"elements": [
				"modularmachinery:blockcasing@2"
			]
		}, {
			"x": 3,
			"y": 6,
			"z": 9,
			"elements": [
				"modularmachinery:blockcasing@0"
			]
		}, {
			"x": 1,
			"y": 2,
			"z": 7,
			"elements": [
				"modularmachinery:blockcasing@2"
			]
		}, {
			"x": 4,
			"y": 6,
			"z": 9,
			"elements": [
				"modularmachinery:blockcasing@0"
			]
		}, {
			"x": 2,
			"y": 2,
			"z": 7,
			"elements": [
				"modularmachinery:blockcasing@2"
			]
		}, {
			"x": 5,
			"y": 6,
			"z": 9,
			"elements": [
				"mysticalagriculture:ingot_storage@6"
			]
		}, {
			"x": 3,
			"y": 2,
			"z": 7,
			"elements": [
				"modularmachinery:blockcasing@4"
			]
		}, {
			"x": 4,
			"y": 2,
			"z": 7,
			"elements": [
				"modularmachinery:blockcasing@0"
			]
		}, {
			"x": 5,
			"y": 2,
			"z": 7,
			"elements": [
				"xtones:zane@1"
			]
		}, {
			"x": -5,
			"y": 7,
			"z": 9,
			"elements": [
				"mysticalagriculture:ingot_storage@6"
			]
		}, {
			"x": -4,
			"y": 7,
			"z": 9,
			"elements": [
				"modularmachinery:blockcasing@0"
			]
		}, {
			"x": -5,
			"y": 3,
			"z": 7,
			"elements": [
				"xtones:zane@1"
			]
		}, {
			"x": -3,
			"y": 7,
			"z": 9,
			"elements": [
				"modularmachinery:blockcasing@0"
			]
		}, {
			"x": -4,
			"y": 3,
			"z": 7,
			"elements": [
				"modularmachinery:blockcasing@0"
			]
		}, {
			"x": -2,
			"y": 7,
			"z": 9,
			"elements": [
				"modularmachinery:blockcasing@0"
			]
		}, {
			"x": -3,
			"y": 3,
			"z": 7,
			"elements": [
				"modularmachinery:blockcasing@4"
			]
		}, {
			"x": -1,
			"y": 7,
			"z": 9,
			"elements": [
				"modularmachinery:blockcasing@0"
			]
		}, {
			"x": 0,
			"y": 7,
			"z": 9,
			"elements": [
				"modularmachinery:blockcasing@0"
			]
		}, {
			"x": -2,
			"y": 3,
			"z": 7,
			"elements": [
				"modularmachinery:blockcasing@2"
			]
		}, {
			"x": -1,
			"y": 3,
			"z": 7,
			"elements": [
				"modularmachinery:blockcasing@2"
			]
		}, {
			"x": 1,
			"y": 7,
			"z": 9,
			"elements": [
				"modularmachinery:blockcasing@0"
			]
		}, {
			"x": 2,
			"y": 7,
			"z": 9,
			"elements": [
				"modularmachinery:blockcasing@0"
			]
		}, {
			"x": 0,
			"y": 3,
			"z": 7,
			"elements": [
				"modularmachinery:blockcasing@2"
			]
		}, {
			"x": 3,
			"y": 7,
			"z": 9,
			"elements": [
				"modularmachinery:blockcasing@0"
			]
		}, {
			"x": 1,
			"y": 3,
			"z": 7,
			"elements": [
				"modularmachinery:blockcasing@2"
			]
		}, {
			"x": 4,
			"y": 7,
			"z": 9,
			"elements": [
				"modularmachinery:blockcasing@0"
			]
		}, {
			"x": 2,
			"y": 3,
			"z": 7,
			"elements": [
				"modularmachinery:blockcasing@2"
			]
		}, {
			"x": 5,
			"y": 7,
			"z": 9,
			"elements": [
				"mysticalagriculture:ingot_storage@6"
			]
		}, {
			"x": 3,
			"y": 3,
			"z": 7,
			"elements": [
				"modularmachinery:blockcasing@4"
			]
		}, {
			"x": 4,
			"y": 3,
			"z": 7,
			"elements": [
				"modularmachinery:blockcasing@0"
			]
		}, {
			"x": 5,
			"y": 3,
			"z": 7,
			"elements": [
				"xtones:zane@1"
			]
		}, {
			"x": -5,
			"y": 8,
			"z": 9,
			"elements": [
				"xtones:zane@1"
			]
		}, {
			"x": -4,
			"y": 8,
			"z": 9,
			"elements": [
				"modularmachinery:blockcasing@0"
			]
		}, {
			"x": -5,
			"y": 4,
			"z": 7,
			"elements": [
				"xtones:zane@1"
			]
		}, {
			"x": -3,
			"y": 8,
			"z": 9,
			"elements": [
				"modularmachinery:blockcasing@0"
			]
		}, {
			"x": -4,
			"y": 4,
			"z": 7,
			"elements": [
				"modularmachinery:blockcasing@0"
			]
		}, {
			"x": -2,
			"y": 8,
			"z": 9,
			"elements": [
				"modularmachinery:blockcasing@0"
			]
		}, {
			"x": -5,
			"y": 0,
			"z": 5,
			"elements": [
				"mysticalagriculture:ingot_storage@6"
			]
		}, {
			"x": -3,
			"y": 4,
			"z": 7,
			"elements": [
				"modularmachinery:blockcasing@4"
			]
		}, {
			"x": -1,
			"y": 8,
			"z": 9,
			"elements": [
				"modularmachinery:blockcasing@0"
			]
		}, {
			"x": 0,
			"y": 8,
			"z": 9,
			"elements": [
				"modularmachinery:blockcasing@0"
			]
		}, {
			"x": -4,
			"y": 0,
			"z": 5,
			"elements": [
				"modularmachinery:blockcasing@0"
			]
		}, {
			"x": -2,
			"y": 4,
			"z": 7,
			"elements": [
				"modularmachinery:blockcasing@2"
			]
		}, {
			"x": -3,
			"y": 0,
			"z": 5,
			"elements": [
				"modularmachinery:blockcasing@4"
			]
		}, {
			"x": -1,
			"y": 4,
			"z": 7,
			"elements": [
				"modularmachinery:blockcasing@2"
			]
		}, {
			"x": 1,
			"y": 8,
			"z": 9,
			"elements": [
				"modularmachinery:blockcasing@0"
			]
		}, {
			"x": 2,
			"y": 8,
			"z": 9,
			"elements": [
				"modularmachinery:blockcasing@0"
			]
		}, {
			"x": 0,
			"y": 4,
			"z": 7,
			"elements": [
				"modularmachinery:blockcasing@2"
			]
		}, {
			"x": -2,
			"y": 0,
			"z": 5,
			"elements": [
				"modularmachinery:blockcasing@2"
			]
		}, {
			"x": -1,
			"y": 0,
			"z": 5,
			"elements": [
				"mysticalagriculture:ingot_storage@6"
			]
		}, {
			"x": 3,
			"y": 8,
			"z": 9,
			"elements": [
				"modularmachinery:blockcasing@0"
			]
		}, {
			"x": 1,
			"y": 4,
			"z": 7,
			"elements": [
				"modularmachinery:blockcasing@2"
			]
		}, {
			"x": 0,
			"y": 0,
			"z": 5,
			"elements": [
				"mysticalagriculture:ingot_storage@6"
			]
		}, {
			"x": 4,
			"y": 8,
			"z": 9,
			"elements": [
				"modularmachinery:blockcasing@0"
			]
		}, {
			"x": 2,
			"y": 4,
			"z": 7,
			"elements": [
				"modularmachinery:blockcasing@2"
			]
		}, {
			"x": 5,
			"y": 8,
			"z": 9,
			"elements": [
				"xtones:zane@1"
			]
		}, {
			"x": 3,
			"y": 4,
			"z": 7,
			"elements": [
				"modularmachinery:blockcasing@4"
			]
		}, {
			"x": 1,
			"y": 0,
			"z": 5,
			"elements": [
				"mysticalagriculture:ingot_storage@6"
			]
		}, {
			"x": 4,
			"y": 4,
			"z": 7,
			"elements": [
				"modularmachinery:blockcasing@0"
			]
		}, {
			"x": 2,
			"y": 0,
			"z": 5,
			"elements": [
				"modularmachinery:blockcasing@2"
			]
		}, {
			"x": 5,
			"y": 4,
			"z": 7,
			"elements": [
				"xtones:zane@1"
			]
		}, {
			"x": 3,
			"y": 0,
			"z": 5,
			"elements": [
				"modularmachinery:blockcasing@4"
			]
		}, {
			"x": 4,
			"y": 0,
			"z": 5,
			"elements": [
				"modularmachinery:blockcasing@0"
			]
		}, {
			"x": 5,
			"y": 0,
			"z": 5,
			"elements": [
				"mysticalagriculture:ingot_storage@6"
			]
		}, {
			"x": -5,
			"y": 9,
			"z": 9,
			"elements": [
				"xtones:zane@1"
			]
		}, {
			"x": -4,
			"y": 9,
			"z": 9,
			"elements": [
				"modularmachinery:blockcasing@0"
			]
		}, {
			"x": -5,
			"y": 5,
			"z": 7,
			"elements": [
				"mysticalagriculture:ingot_storage@6"
			]
		}, {
			"x": -3,
			"y": 9,
			"z": 9,
			"elements": [
				"modularmachinery:blockcasing@0"
			]
		}, {
			"x": -4,
			"y": 5,
			"z": 7,
			"elements": [
				"modularmachinery:blockcasing@0"
			]
		}, {
			"x": -2,
			"y": 9,
			"z": 9,
			"elements": [
				"modularmachinery:blockcasing@0"
			]
		}, {
			"x": -5,
			"y": 1,
			"z": 5,
			"elements": [
				"mysticalagriculture:ingot_storage@6"
			]
		}, {
			"x": -3,
			"y": 5,
			"z": 7,
			"elements": [
				"modularmachinery:blockcasing@4"
			]
		}, {
			"x": -1,
			"y": 9,
			"z": 9,
			"elements": [
				"modularmachinery:blockcasing@0"
			]
		}, {
			"x": 0,
			"y": 9,
			"z": 9,
			"elements": [
				"modularmachinery:blockcasing@0"
			]
		}, {
			"x": -4,
			"y": 1,
			"z": 5,
			"elements": [
				"modularmachinery:blockcasing@0"
			]
		}, {
			"x": -2,
			"y": 5,
			"z": 7,
			"elements": [
				"modularmachinery:blockcasing@2"
			]
		}, {
			"x": -3,
			"y": 1,
			"z": 5,
			"elements": [
				"modularmachinery:blockcasing@4"
			]
		}, {
			"x": -1,
			"y": 5,
			"z": 7,
			"elements": [
				"modularmachinery:blockcasing@2"
			]
		}, {
			"x": 1,
			"y": 9,
			"z": 9,
			"elements": [
				"modularmachinery:blockcasing@0"
			]
		}, {
			"x": 2,
			"y": 9,
			"z": 9,
			"elements": [
				"modularmachinery:blockcasing@0"
			]
		}, {
			"x": 0,
			"y": 5,
			"z": 7,
			"elements": [
				"modularmachinery:blockcasing@2"
			]
		}, {
			"x": -2,
			"y": 1,
			"z": 5,
			"elements": [
				"modularmachinery:blockcasing@2"
			]
		}, {
			"x": -1,
			"y": 1,
			"z": 5,
			"elements": [
				"draconicevolution:draconic_block@0"
			]
		}, {
			"x": 3,
			"y": 9,
			"z": 9,
			"elements": [
				"modularmachinery:blockcasing@0"
			]
		}, {
			"x": 1,
			"y": 5,
			"z": 7,
			"elements": [
				"modularmachinery:blockcasing@2"
			]
		}, {
			"x": 4,
			"y": 9,
			"z": 9,
			"elements": [
				"modularmachinery:blockcasing@0"
			]
		}, {
			"x": 2,
			"y": 5,
			"z": 7,
			"elements": [
				"modularmachinery:blockcasing@2"
			]
		}, {
			"x": 0,
			"y": 1,
			"z": 5,
			"elements": [
				"draconicevolution:draconic_block@0"
			]
		}, {
			"x": 5,
			"y": 9,
			"z": 9,
			"elements": [
				"xtones:zane@1"
			]
		}, {
			"x": 3,
			"y": 5,
			"z": 7,
			"elements": [
				"modularmachinery:blockcasing@4"
			]
		}, {
			"x": 1,
			"y": 1,
			"z": 5,
			"elements": [
				"draconicevolution:draconic_block@0"
			]
		}, {
			"x": 4,
			"y": 5,
			"z": 7,
			"elements": [
				"modularmachinery:blockcasing@0"
			]
		}, {
			"x": 2,
			"y": 1,
			"z": 5,
			"elements": [
				"modularmachinery:blockcasing@2"
			]
		}, {
			"x": 5,
			"y": 5,
			"z": 7,
			"elements": [
				"mysticalagriculture:ingot_storage@6"
			]
		}, {
			"x": 3,
			"y": 1,
			"z": 5,
			"elements": [
				"modularmachinery:blockcasing@4"
			]
		}, {
			"x": 4,
			"y": 1,
			"z": 5,
			"elements": [
				"modularmachinery:blockcasing@0"
			]
		}, {
			"x": 5,
			"y": 1,
			"z": 5,
			"elements": [
				"mysticalagriculture:ingot_storage@6"
			]
		}, {
			"x": -5,
			"y": 10,
			"z": 9,
			"elements": [
				"mysticalagriculture:ingot_storage@6"
			]
		}, {
			"x": -4,
			"y": 10,
			"z": 9,
			"elements": [
				"draconicevolution:infused_obsidian@0"
			]
		}, {
			"x": -5,
			"y": 6,
			"z": 7,
			"elements": [
				"xtones:zane@1"
			]
		}, {
			"x": -3,
			"y": 10,
			"z": 9,
			"elements": [
				"draconicevolution:infused_obsidian@0"
			]
		}, {
			"x": -4,
			"y": 6,
			"z": 7,
			"elements": [
				"modularmachinery:blockcasing@0"
			]
		}, {
			"x": -2,
			"y": 10,
			"z": 9,
			"elements": [
				"draconicevolution:infused_obsidian@0"
			]
		}, {
			"x": -5,
			"y": 2,
			"z": 5,
			"elements": [
				"mysticalagriculture:ingot_storage@6"
			]
		}, {
			"x": -3,
			"y": 6,
			"z": 7,
			"elements": [
				"modularmachinery:blockcasing@4"
			]
		}, {
			"x": -1,
			"y": 10,
			"z": 9,
			"elements": [
				"draconicevolution:infused_obsidian@0"
			]
		}, {
			"x": 0,
			"y": 10,
			"z": 9,
			"elements": [
				"draconicevolution:infused_obsidian@0"
			]
		}, {
			"x": -4,
			"y": 2,
			"z": 5,
			"elements": [
				"modularmachinery:blockcasing@0"
			]
		}, {
			"x": -2,
			"y": 6,
			"z": 7,
			"elements": [
				"modularmachinery:blockcasing@2"
			]
		}, {
			"x": -3,
			"y": 2,
			"z": 5,
			"elements": [
				"modularmachinery:blockcasing@4"
			]
		}, {
			"x": -1,
			"y": 6,
			"z": 7,
			"elements": [
				"modularmachinery:blockcasing@2"
			]
		}, {
			"x": 1,
			"y": 10,
			"z": 9,
			"elements": [
				"draconicevolution:infused_obsidian@0"
			]
		}, {
			"x": 2,
			"y": 10,
			"z": 9,
			"elements": [
				"draconicevolution:infused_obsidian@0"
			]
		}, {
			"x": 0,
			"y": 6,
			"z": 7,
			"elements": [
				"modularmachinery:blockcasing@2"
			]
		}, {
			"x": -2,
			"y": 2,
			"z": 5,
			"elements": [
				"modularmachinery:blockcasing@2"
			]
		}, {
			"x": -1,
			"y": 2,
			"z": 5,
			"elements": [
				"draconicevolution:draconic_block@0"
			]
		}, {
			"x": 3,
			"y": 10,
			"z": 9,
			"elements": [
				"draconicevolution:infused_obsidian@0"
			]
		}, {
			"x": 1,
			"y": 6,
			"z": 7,
			"elements": [
				"modularmachinery:blockcasing@2"
			]
		}, {
			"x": 4,
			"y": 10,
			"z": 9,
			"elements": [
				"draconicevolution:infused_obsidian@0"
			]
		}, {
			"x": 2,
			"y": 6,
			"z": 7,
			"elements": [
				"modularmachinery:blockcasing@2"
			]
		}, {
			"x": 0,
			"y": 2,
			"z": 5,
			"elements": [
				"draconicevolution:draconic_block@0"
			]
		}, {
			"x": 5,
			"y": 10,
			"z": 9,
			"elements": [
				"mysticalagriculture:ingot_storage@6"
			]
		}, {
			"x": 3,
			"y": 6,
			"z": 7,
			"elements": [
				"modularmachinery:blockcasing@4"
			]
		}, {
			"x": 1,
			"y": 2,
			"z": 5,
			"elements": [
				"draconicevolution:draconic_block@0"
			]
		}, {
			"x": 4,
			"y": 6,
			"z": 7,
			"elements": [
				"modularmachinery:blockcasing@0"
			]
		}, {
			"x": 2,
			"y": 2,
			"z": 5,
			"elements": [
				"modularmachinery:blockcasing@2"
			]
		}, {
			"x": 5,
			"y": 6,
			"z": 7,
			"elements": [
				"xtones:zane@1"
			]
		}, {
			"x": 3,
			"y": 2,
			"z": 5,
			"elements": [
				"modularmachinery:blockcasing@4"
			]
		}, {
			"x": 4,
			"y": 2,
			"z": 5,
			"elements": [
				"modularmachinery:blockcasing@0"
			]
		}, {
			"x": 5,
			"y": 2,
			"z": 5,
			"elements": [
				"mysticalagriculture:ingot_storage@6"
			]
		}, {
			"x": -5,
			"y": 11,
			"z": 9,
			"elements": [
				"extrautils2:cursedearth@0"
			]
		}, {
			"x": -4,
			"y": 11,
			"z": 9,
			"elements": [
				"extrautils2:cursedearth@0"
			]
		}, {
			"x": -5,
			"y": 7,
			"z": 7,
			"elements": [
				"xtones:zane@1"
			]
		}, {
			"x": -3,
			"y": 11,
			"z": 9,
			"elements": [
				"extrautils2:cursedearth@0"
			]
		}, {
			"x": -4,
			"y": 7,
			"z": 7,
			"elements": [
				"modularmachinery:blockcasing@0"
			]
		}, {
			"x": -2,
			"y": 11,
			"z": 9,
			"elements": [
				"extrautils2:cursedearth@0"
			]
		}, {
			"x": -5,
			"y": 3,
			"z": 5,
			"elements": [
				"mysticalagriculture:ingot_storage@6"
			]
		}, {
			"x": -3,
			"y": 7,
			"z": 7,
			"elements": [
				"modularmachinery:blockcasing@4"
			]
		}, {
			"x": -1,
			"y": 11,
			"z": 9,
			"elements": [
				"extrautils2:cursedearth@0"
			]
		}, {
			"x": 0,
			"y": 11,
			"z": 9,
			"elements": [
				"extrautils2:cursedearth@0"
			]
		}, {
			"x": -4,
			"y": 3,
			"z": 5,
			"elements": [
				"modularmachinery:blockcasing@0"
			]
		}, {
			"x": -2,
			"y": 7,
			"z": 7,
			"elements": [
				"modularmachinery:blockcasing@2"
			]
		}, {
			"x": -3,
			"y": 3,
			"z": 5,
			"elements": [
				"modularmachinery:blockcasing@4"
			]
		}, {
			"x": -1,
			"y": 7,
			"z": 7,
			"elements": [
				"modularmachinery:blockcasing@2"
			]
		}, {
			"x": 1,
			"y": 11,
			"z": 9,
			"elements": [
				"extrautils2:cursedearth@0"
			]
		}, {
			"x": 2,
			"y": 11,
			"z": 9,
			"elements": [
				"extrautils2:cursedearth@0"
			]
		}, {
			"x": 0,
			"y": 7,
			"z": 7,
			"elements": [
				"actuallyadditions:block_display_stand@0"
			]
		}, {
			"x": -2,
			"y": 3,
			"z": 5,
			"elements": [
				"modularmachinery:blockcasing@2"
			]
		}, {
			"x": -1,
			"y": 3,
			"z": 5,
			"elements": [
				"draconicevolution:draconic_block@0"
			]
		}, {
			"x": 3,
			"y": 11,
			"z": 9,
			"elements": [
				"extrautils2:cursedearth@0"
			]
		}, {
			"x": 1,
			"y": 7,
			"z": 7,
			"elements": [
				"modularmachinery:blockcasing@2"
			]
		}, {
			"x": 4,
			"y": 11,
			"z": 9,
			"elements": [
				"extrautils2:cursedearth@0"
			]
		}, {
			"x": 2,
			"y": 7,
			"z": 7,
			"elements": [
				"modularmachinery:blockcasing@2"
			]
		}, {
			"x": 0,
			"y": 3,
			"z": 5,
			"elements": [
				"draconicevolution:draconic_block@0"
			]
		}, {
			"x": 5,
			"y": 11,
			"z": 9,
			"elements": [
				"extrautils2:cursedearth@0"
			]
		}, {
			"x": 3,
			"y": 7,
			"z": 7,
			"elements": [
				"modularmachinery:blockcasing@4"
			]
		}, {
			"x": 1,
			"y": 3,
			"z": 5,
			"elements": [
				"draconicevolution:draconic_block@0"
			]
		}, {
			"x": 4,
			"y": 7,
			"z": 7,
			"elements": [
				"modularmachinery:blockcasing@0"
			]
		}, {
			"x": 2,
			"y": 3,
			"z": 5,
			"elements": [
				"modularmachinery:blockcasing@2"
			]
		}, {
			"x": 5,
			"y": 7,
			"z": 7,
			"elements": [
				"xtones:zane@1"
			]
		}, {
			"x": 3,
			"y": 3,
			"z": 5,
			"elements": [
				"modularmachinery:blockcasing@4"
			]
		}, {
			"x": 4,
			"y": 3,
			"z": 5,
			"elements": [
				"modularmachinery:blockcasing@0"
			]
		}, {
			"x": 5,
			"y": 3,
			"z": 5,
			"elements": [
				"mysticalagriculture:ingot_storage@6"
			]
		}, {
			"x": -5,
			"y": 8,
			"z": 7,
			"elements": [
				"xtones:zane@1"
			]
		}, {
			"x": -4,
			"y": 8,
			"z": 7,
			"elements": [
				"modularmachinery:blockcasing@0"
			]
		}, {
			"x": -5,
			"y": 4,
			"z": 5,
			"elements": [
				"xtones:zane@1"
			]
		}, {
			"x": -3,
			"y": 8,
			"z": 7,
			"elements": [
				"modularmachinery:blockcasing@4"
			]
		}, {
			"x": -4,
			"y": 4,
			"z": 5,
			"elements": [
				"modularmachinery:blockcasing@0"
			]
		}, {
			"x": -2,
			"y": 8,
			"z": 7,
			"elements": [
				"extrautils2:compressedcobblestone@7"
			]
		}, {
			"x": -5,
			"y": 0,
			"z": 3,
			"elements": [
				"mysticalagriculture:ingot_storage@6"
			]
		}, {
			"x": -3,
			"y": 4,
			"z": 5,
			"elements": [
				"modularmachinery:blockcasing@4"
			]
		}, {
			"x": -1,
			"y": 8,
			"z": 7,
			"elements": [
				"extrautils2:compressedcobblestone@7"
			]
		}, {
			"x": 0,
			"y": 8,
			"z": 7,
			"elements": [
				"extrautils2:compressedcobblestone@7"
			]
		}, {
			"x": -4,
			"y": 0,
			"z": 3,
			"elements": [
				"modularmachinery:blockcasing@0"
			]
		}, {
			"x": -2,
			"y": 4,
			"z": 5,
			"elements": [
				"modularmachinery:blockcasing@2"
			]
		}, {
			"x": -3,
			"y": 0,
			"z": 3,
			"elements": [
				"modularmachinery:blockcasing@4"
			]
		}, {
			"x": -1,
			"y": 4,
			"z": 5,
			"elements": [
				"extrautils2:compressednetherrack@5"
			]
		}, {
			"x": 1,
			"y": 8,
			"z": 7,
			"elements": [
				"extrautils2:compressedcobblestone@7"
			]
		}, {
			"x": 2,
			"y": 8,
			"z": 7,
			"elements": [
				"extrautils2:compressedcobblestone@7"
			]
		}, {
			"x": 0,
			"y": 4,
			"z": 5,
			"elements": [
				"extrautils2:compressednetherrack@5"
			]
		}, {
			"x": -2,
			"y": 0,
			"z": 3,
			"elements": [
				"modularmachinery:blockcasing@2"
			]
		}, {
			"x": -1,
			"y": 0,
			"z": 3,
			"elements": [
				"modularmachinery:blockcasing@2"
			]
		}, {
			"x": 3,
			"y": 8,
			"z": 7,
			"elements": [
				"modularmachinery:blockcasing@4"
			]
		}, {
			"x": 1,
			"y": 4,
			"z": 5,
			"elements": [
				"extrautils2:compressednetherrack@5"
			]
		}, {
			"x": 0,
			"y": 0,
			"z": 3,
			"elements": [
				"modularmachinery:blockcasing@2"
			]
		}, {
			"x": 4,
			"y": 8,
			"z": 7,
			"elements": [
				"modularmachinery:blockcasing@0"
			]
		}, {
			"x": 2,
			"y": 4,
			"z": 5,
			"elements": [
				"modularmachinery:blockcasing@2"
			]
		}, {
			"x": 5,
			"y": 8,
			"z": 7,
			"elements": [
				"xtones:zane@1"
			]
		}, {
			"x": 3,
			"y": 4,
			"z": 5,
			"elements": [
				"modularmachinery:blockcasing@4"
			]
		}, {
			"x": 1,
			"y": 0,
			"z": 3,
			"elements": [
				"modularmachinery:blockcasing@2"
			]
		}, {
			"x": 4,
			"y": 4,
			"z": 5,
			"elements": [
				"modularmachinery:blockcasing@0"
			]
		}, {
			"x": 2,
			"y": 0,
			"z": 3,
			"elements": [
				"modularmachinery:blockcasing@2"
			]
		}, {
			"x": 5,
			"y": 4,
			"z": 5,
			"elements": [
				"xtones:zane@1"
			]
		}, {
			"x": 3,
			"y": 0,
			"z": 3,
			"elements": [
				"modularmachinery:blockcasing@4"
			]
		}, {
			"x": 4,
			"y": 0,
			"z": 3,
			"elements": [
				"modularmachinery:blockcasing@0"
			]
		}, {
			"x": 5,
			"y": 0,
			"z": 3,
			"elements": [
				"mysticalagriculture:ingot_storage@6"
			]
		}, {
			"x": -5,
			"y": 9,
			"z": 7,
			"elements": [
				"mysticalagriculture:ingot_storage@6"
			]
		}, {
			"x": -4,
			"y": 9,
			"z": 7,
			"elements": [
				"modularmachinery:blockcasing@0"
			]
		}, {
			"x": -5,
			"y": 5,
			"z": 5,
			"elements": [
				"xtones:zane@1"
			]
		}, {
			"x": -3,
			"y": 9,
			"z": 7,
			"elements": [
				"thermalfoundation:fluid_cryotheum@0"
			]
		}, {
			"x": -4,
			"y": 5,
			"z": 5,
			"elements": [
				"modularmachinery:blockcasing@0"
			]
		}, {
			"x": -2,
			"y": 9,
			"z": 7,
			"elements": [
				"extrautils2:compresseddirt@3"
			]
		}, {
			"x": -5,
			"y": 1,
			"z": 3,
			"elements": [
				"mysticalagriculture:ingot_storage@6"
			]
		}, {
			"x": -3,
			"y": 5,
			"z": 5,
			"elements": [
				"modularmachinery:blockcasing@4"
			]
		}, {
			"x": -1,
			"y": 9,
			"z": 7,
			"elements": [
				"extrautils2:compresseddirt@3"
			]
		}, {
			"x": 0,
			"y": 9,
			"z": 7,
			"elements": [
				"extrautils2:compresseddirt@3"
			]
		}, {
			"x": -4,
			"y": 1,
			"z": 3,
			"elements": [
				"modularmachinery:blockcasing@0"
			]
		}, {
			"x": -2,
			"y": 5,
			"z": 5,
			"elements": [
				"modularmachinery:blockcasing@2"
			]
		}, {
			"x": -3,
			"y": 1,
			"z": 3,
			"elements": [
				"modularmachinery:blockcasing@4"
			]
		}, {
			"x": -1,
			"y": 5,
			"z": 5,
			"elements": [
				"extrautils2:compressednetherrack@5"
			]
		}, {
			"x": 1,
			"y": 9,
			"z": 7,
			"elements": [
				"extrautils2:compresseddirt@3"
			]
		}, {
			"x": 2,
			"y": 9,
			"z": 7,
			"elements": [
				"extrautils2:compresseddirt@3"
			]
		}, {
			"x": 0,
			"y": 5,
			"z": 5,
			"elements": [
				"extrautils2:compressednetherrack@5"
			]
		}, {
			"x": -2,
			"y": 1,
			"z": 3,
			"elements": [
				"modularmachinery:blockcasing@2"
			]
		}, {
			"x": -1,
			"y": 1,
			"z": 3,
			"elements": [
				"modularmachinery:blockcasing@2"
			]
		}, {
			"x": 3,
			"y": 9,
			"z": 7,
			"elements": [
				"thermalfoundation:fluid_cryotheum@0"
			]
		}, {
			"x": 1,
			"y": 5,
			"z": 5,
			"elements": [
				"extrautils2:compressednetherrack@5"
			]
		}, {
			"x": 4,
			"y": 9,
			"z": 7,
			"elements": [
				"modularmachinery:blockcasing@0"
			]
		}, {
			"x": 2,
			"y": 5,
			"z": 5,
			"elements": [
				"modularmachinery:blockcasing@2"
			]
		}, {
			"x": 0,
			"y": 1,
			"z": 3,
			"elements": [
				"modularmachinery:blockcasing@2"
			]
		}, {
			"x": 5,
			"y": 9,
			"z": 7,
			"elements": [
				"mysticalagriculture:ingot_storage@6"
			]
		}, {
			"x": 3,
			"y": 5,
			"z": 5,
			"elements": [
				"modularmachinery:blockcasing@4"
			]
		}, {
			"x": 1,
			"y": 1,
			"z": 3,
			"elements": [
				"modularmachinery:blockcasing@2"
			]
		}, {
			"x": 4,
			"y": 5,
			"z": 5,
			"elements": [
				"modularmachinery:blockcasing@0"
			]
		}, {
			"x": 2,
			"y": 1,
			"z": 3,
			"elements": [
				"modularmachinery:blockcasing@2"
			]
		}, {
			"x": 5,
			"y": 5,
			"z": 5,
			"elements": [
				"xtones:zane@1"
			]
		}, {
			"x": 3,
			"y": 1,
			"z": 3,
			"elements": [
				"modularmachinery:blockcasing@4"
			]
		}, {
			"x": 4,
			"y": 1,
			"z": 3,
			"elements": [
				"modularmachinery:blockcasing@0"
			]
		}, {
			"x": 5,
			"y": 1,
			"z": 3,
			"elements": [
				"mysticalagriculture:ingot_storage@6"
			]
		}, {
			"x": -5,
			"y": 10,
			"z": 7,
			"elements": [
				"mysticalagriculture:ingot_storage@6"
			]
		}, {
			"x": -4,
			"y": 10,
			"z": 7,
			"elements": [
				"draconicevolution:infused_obsidian@0"
			]
		}, {
			"x": -5,
			"y": 6,
			"z": 5,
			"elements": [
				"xtones:zane@1"
			]
		}, {
			"x": -3,
			"y": 10,
			"z": 7,
			"elements": [
				"draconicevolution:infused_obsidian@0"
			]
		}, {
			"x": -4,
			"y": 6,
			"z": 5,
			"elements": [
				"modularmachinery:blockcasing@0"
			]
		}, {
			"x": -2,
			"y": 10,
			"z": 7,
			"elements": [
				"draconicevolution:draconium_block@1"
			]
		}, {
			"x": -5,
			"y": 2,
			"z": 3,
			"elements": [
				"xtones:zane@1"
			]
		}, {
			"x": -3,
			"y": 6,
			"z": 5,
			"elements": [
				"modularmachinery:blockcasing@4"
			]
		}, {
			"x": -1,
			"y": 10,
			"z": 7,
			"elements": [
				"draconicevolution:draconium_block@1"
			]
		}, {
			"x": 0,
			"y": 10,
			"z": 7,
			"elements": [
				"draconicevolution:draconium_block@1"
			]
		}, {
			"x": -4,
			"y": 2,
			"z": 3,
			"elements": [
				"modularmachinery:blockcasing@0"
			]
		}, {
			"x": -2,
			"y": 6,
			"z": 5,
			"elements": [
				"modularmachinery:blockcasing@2"
			]
		}, {
			"x": -3,
			"y": 2,
			"z": 3,
			"elements": [
				"modularmachinery:blockcasing@4"
			]
		}, {
			"x": -1,
			"y": 6,
			"z": 5,
			"elements": [
				"extrautils2:compressednetherrack@5"
			]
		}, {
			"x": 1,
			"y": 10,
			"z": 7,
			"elements": [
				"draconicevolution:draconium_block@1"
			]
		}, {
			"x": 2,
			"y": 10,
			"z": 7,
			"elements": [
				"draconicevolution:draconium_block@1"
			]
		}, {
			"x": 0,
			"y": 6,
			"z": 5,
			"elements": [
				"extrautils2:compressednetherrack@5"
			]
		}, {
			"x": -2,
			"y": 2,
			"z": 3,
			"elements": [
				"modularmachinery:blockcasing@2"
			]
		}, {
			"x": -1,
			"y": 2,
			"z": 3,
			"elements": [
				"modularmachinery:blockcasing@2"
			]
		}, {
			"x": 3,
			"y": 10,
			"z": 7,
			"elements": [
				"draconicevolution:infused_obsidian@0"
			]
		}, {
			"x": 1,
			"y": 6,
			"z": 5,
			"elements": [
				"extrautils2:compressednetherrack@5"
			]
		}, {
			"x": 4,
			"y": 10,
			"z": 7,
			"elements": [
				"draconicevolution:infused_obsidian@0"
			]
		}, {
			"x": 2,
			"y": 6,
			"z": 5,
			"elements": [
				"modularmachinery:blockcasing@2"
			]
		}, {
			"x": 0,
			"y": 2,
			"z": 3,
			"elements": [
				"modularmachinery:blockcasing@2"
			]
		}, {
			"x": 5,
			"y": 10,
			"z": 7,
			"elements": [
				"mysticalagriculture:ingot_storage@6"
			]
		}, {
			"x": 3,
			"y": 6,
			"z": 5,
			"elements": [
				"modularmachinery:blockcasing@4"
			]
		}, {
			"x": 1,
			"y": 2,
			"z": 3,
			"elements": [
				"modularmachinery:blockcasing@2"
			]
		}, {
			"x": 4,
			"y": 6,
			"z": 5,
			"elements": [
				"modularmachinery:blockcasing@0"
			]
		}, {
			"x": 2,
			"y": 2,
			"z": 3,
			"elements": [
				"modularmachinery:blockcasing@2"
			]
		}, {
			"x": 5,
			"y": 6,
			"z": 5,
			"elements": [
				"xtones:zane@1"
			]
		}, {
			"x": 3,
			"y": 2,
			"z": 3,
			"elements": [
				"modularmachinery:blockcasing@4"
			]
		}, {
			"x": 4,
			"y": 2,
			"z": 3,
			"elements": [
				"modularmachinery:blockcasing@0"
			]
		}, {
			"x": 5,
			"y": 2,
			"z": 3,
			"elements": [
				"xtones:zane@1"
			]
		}, {
			"x": -5,
			"y": 11,
			"z": 7,
			"elements": [
				"extrautils2:cursedearth@0"
			]
		}, {
			"x": -4,
			"y": 11,
			"z": 7,
			"elements": [
				"extrautils2:cursedearth@0"
			]
		}, {
			"x": -5,
			"y": 7,
			"z": 5,
			"elements": [
				"mysticalagriculture:ingot_storage@6"
			]
		}, {
			"x": -3,
			"y": 11,
			"z": 7,
			"elements": [
				"extrautils2:cursedearth@0"
			]
		}, {
			"x": -4,
			"y": 7,
			"z": 5,
			"elements": [
				"modularmachinery:blockcasing@0"
			]
		}, {
			"x": -2,
			"y": 11,
			"z": 7,
			"elements": [
				"extrautils2:cursedearth@0"
			]
		}, {
			"x": -5,
			"y": 3,
			"z": 3,
			"elements": [
				"xtones:zane@1"
			]
		}, {
			"x": -3,
			"y": 7,
			"z": 5,
			"elements": [
				"modularmachinery:blockcasing@4"
			]
		}, {
			"x": -1,
			"y": 11,
			"z": 7,
			"elements": [
				"extrautils2:cursedearth@0"
			]
		}, {
			"x": 0,
			"y": 11,
			"z": 7,
			"elements": [
				"extrautils2:cursedearth@0"
			]
		}, {
			"x": -4,
			"y": 3,
			"z": 3,
			"elements": [
				"modularmachinery:blockcasing@0"
			]
		}, {
			"x": -2,
			"y": 7,
			"z": 5,
			"elements": [
				"actuallyadditions:block_display_stand@0"
			]
		}, {
			"x": -3,
			"y": 3,
			"z": 3,
			"elements": [
				"modularmachinery:blockcasing@4"
			]
		}, {
			"x": -1,
			"y": 7,
			"z": 5,
			"elements": [
				"thermalfoundation:fluid_pyrotheum@0"
			]
		}, {
			"x": 1,
			"y": 11,
			"z": 7,
			"elements": [
				"extrautils2:cursedearth@0"
			]
		}, {
			"x": 2,
			"y": 11,
			"z": 7,
			"elements": [
				"extrautils2:cursedearth@0"
			]
		}, {
			"x": -2,
			"y": 3,
			"z": 3,
			"elements": [
				"modularmachinery:blockcasing@2"
			]
		}, {
			"x": -1,
			"y": 3,
			"z": 3,
			"elements": [
				"modularmachinery:blockcasing@2"
			]
		}, {
			"x": 3,
			"y": 11,
			"z": 7,
			"elements": [
				"extrautils2:cursedearth@0"
			]
		}, {
			"x": 1,
			"y": 7,
			"z": 5,
			"elements": [
				"thermalfoundation:fluid_pyrotheum@0"
			]
		}, {
			"x": 4,
			"y": 11,
			"z": 7,
			"elements": [
				"extrautils2:cursedearth@0"
			]
		}, {
			"x": 2,
			"y": 7,
			"z": 5,
			"elements": [
				"actuallyadditions:block_display_stand@0"
			]
		}, {
			"x": 0,
			"y": 3,
			"z": 3,
			"elements": [
				"modularmachinery:blockcasing@2"
			]
		}, {
			"x": 5,
			"y": 11,
			"z": 7,
			"elements": [
				"extrautils2:cursedearth@0"
			]
		}, {
			"x": 3,
			"y": 7,
			"z": 5,
			"elements": [
				"modularmachinery:blockcasing@4"
			]
		}, {
			"x": 1,
			"y": 3,
			"z": 3,
			"elements": [
				"modularmachinery:blockcasing@2"
			]
		}, {
			"x": 4,
			"y": 7,
			"z": 5,
			"elements": [
				"modularmachinery:blockcasing@0"
			]
		}, {
			"x": 2,
			"y": 3,
			"z": 3,
			"elements": [
				"modularmachinery:blockcasing@2"
			]
		}, {
			"x": 5,
			"y": 7,
			"z": 5,
			"elements": [
				"mysticalagriculture:ingot_storage@6"
			]
		}, {
			"x": 3,
			"y": 3,
			"z": 3,
			"elements": [
				"modularmachinery:blockcasing@4"
			]
		}, {
			"x": 4,
			"y": 3,
			"z": 3,
			"elements": [
				"modularmachinery:blockcasing@0"
			]
		}, {
			"x": 5,
			"y": 3,
			"z": 3,
			"elements": [
				"xtones:zane@1"
			]
		}, {
			"x": -5,
			"y": 8,
			"z": 5,
			"elements": [
				"mysticalagriculture:ingot_storage@6"
			]
		}, {
			"x": -4,
			"y": 8,
			"z": 5,
			"elements": [
				"modularmachinery:blockcasing@0"
			]
		}, {
			"x": -5,
			"y": 4,
			"z": 3,
			"elements": [
				"xtones:zane@1"
			]
		}, {
			"x": -3,
			"y": 8,
			"z": 5,
			"elements": [
				"modularmachinery:blockcasing@4"
			]
		}, {
			"x": -4,
			"y": 4,
			"z": 3,
			"elements": [
				"modularmachinery:blockcasing@0"
			]
		}, {
			"x": -2,
			"y": 8,
			"z": 5,
			"elements": [
				"extrautils2:compressedcobblestone@7"
			]
		}, {
			"x": -5,
			"y": 0,
			"z": 1,
			"elements": [
				"mysticalagriculture:ingot_storage@6"
			]
		}, {
			"x": -3,
			"y": 4,
			"z": 3,
			"elements": [
				"modularmachinery:blockcasing@4"
			]
		}, {
			"x": -1,
			"y": 8,
			"z": 5,
			"elements": [
				"extrautils2:compressedcobblestone@7"
			]
		}, {
			"x": 0,
			"y": 8,
			"z": 5,
			"elements": [
				"extrautils2:compressedcobblestone@7"
			]
		}, {
			"x": -4,
			"y": 0,
			"z": 1,
			"elements": [
				"modularmachinery:blockcasing@0"
			]
		}, {
			"x": -2,
			"y": 4,
			"z": 3,
			"elements": [
				"modularmachinery:blockcasing@2"
			]
		}, {
			"x": -3,
			"y": 0,
			"z": 1,
			"elements": [
				"modularmachinery:blockcasing@0"
			]
		}, {
			"x": -1,
			"y": 4,
			"z": 3,
			"elements": [
				"modularmachinery:blockcasing@2"
			]
		}, {
			"x": 1,
			"y": 8,
			"z": 5,
			"elements": [
				"extrautils2:compressedcobblestone@7"
			]
		}, {
			"x": 2,
			"y": 8,
			"z": 5,
			"elements": [
				"extrautils2:compressedcobblestone@7"
			]
		}, {
			"x": 0,
			"y": 4,
			"z": 3,
			"elements": [
				"modularmachinery:blockcasing@2"
			]
		}, {
			"x": -2,
			"y": 0,
			"z": 1,
			"elements": [
				"modularmachinery:blockcasing@0"
			]
		}, {
			"x": -1,
			"y": 0,
			"z": 1,
			"elements": [
				"modularmachinery:blockcasing@0"
			]
		}, {
			"x": 3,
			"y": 8,
			"z": 5,
			"elements": [
				"modularmachinery:blockcasing@4"
			]
		}, {
			"x": 1,
			"y": 4,
			"z": 3,
			"elements": [
				"modularmachinery:blockcasing@2"
			]
		}, {
			"x": 0,
			"y": 0,
			"z": 1,
			"elements": [
				"modularmachinery:blockcasing@0"
			]
		}, {
			"x": 4,
			"y": 8,
			"z": 5,
			"elements": [
				"modularmachinery:blockcasing@0"
			]
		}, {
			"x": 2,
			"y": 4,
			"z": 3,
			"elements": [
				"modularmachinery:blockcasing@2"
			]
		}, {
			"x": 5,
			"y": 8,
			"z": 5,
			"elements": [
				"mysticalagriculture:ingot_storage@6"
			]
		}, {
			"x": 3,
			"y": 4,
			"z": 3,
			"elements": [
				"modularmachinery:blockcasing@4"
			]
		}, {
			"x": 1,
			"y": 0,
			"z": 1,
			"elements": [
				"modularmachinery:blockcasing@0"
			]
		}, {
			"x": 4,
			"y": 4,
			"z": 3,
			"elements": [
				"modularmachinery:blockcasing@0"
			]
		}, {
			"x": 2,
			"y": 0,
			"z": 1,
			"elements": [
				"modularmachinery:blockcasing@0"
			]
		}, {
			"x": 5,
			"y": 4,
			"z": 3,
			"elements": [
				"xtones:zane@1"
			]
		}, {
			"x": 3,
			"y": 0,
			"z": 1,
			"elements": [
				"modularmachinery:blockcasing@0"
			]
		}, {
			"x": 4,
			"y": 0,
			"z": 1,
			"elements": [
				"modularmachinery:blockcasing@0"
			]
		}, {
			"x": 5,
			"y": 0,
			"z": 1,
			"elements": [
				"mysticalagriculture:ingot_storage@6"
			]
		}, {
			"x": -5,
			"y": 9,
			"z": 5,
			"elements": [
				"mysticalagriculture:ingot_storage@6"
			]
		}, {
			"x": -4,
			"y": 9,
			"z": 5,
			"elements": [
				"modularmachinery:blockcasing@0"
			]
		}, {
			"x": -5,
			"y": 5,
			"z": 3,
			"elements": [
				"mysticalagriculture:ingot_storage@6"
			]
		}, {
			"x": -3,
			"y": 9,
			"z": 5,
			"elements": [
				"thermalfoundation:fluid_cryotheum@0"
			]
		}, {
			"x": -4,
			"y": 5,
			"z": 3,
			"elements": [
				"modularmachinery:blockcasing@0"
			]
		}, {
			"x": -2,
			"y": 9,
			"z": 5,
			"elements": [
				"extrautils2:compresseddirt@3"
			]
		}, {
			"x": -5,
			"y": 1,
			"z": 1,
			"elements": [
				"xtones:zane@1"
			]
		}, {
			"x": -3,
			"y": 5,
			"z": 3,
			"elements": [
				"modularmachinery:blockcasing@4"
			]
		}, {
			"x": -1,
			"y": 9,
			"z": 5,
			"elements": [
				"extrautils2:compressedsand@1"
			]
		}, {
			"x": 0,
			"y": 9,
			"z": 5,
			"elements": [
				"extrautils2:compressedgravel@1"
			]
		}, {
			"x": -4,
			"y": 1,
			"z": 1,
			"elements": [
				"modularmachinery:blockcasing@0"
			]
		}, {
			"x": -2,
			"y": 5,
			"z": 3,
			"elements": [
				"modularmachinery:blockcasing@2"
			]
		}, {
			"x": -3,
			"y": 1,
			"z": 1,
			"elements": [
				"modularmachinery:blockcasing@0"
			]
		}, {
			"x": -1,
			"y": 5,
			"z": 3,
			"elements": [
				"modularmachinery:blockcasing@2"
			]
		}, {
			"x": 1,
			"y": 9,
			"z": 5,
			"elements": [
				"extrautils2:compressedsand@1"
			]
		}, {
			"x": 2,
			"y": 9,
			"z": 5,
			"elements": [
				"extrautils2:compresseddirt@3"
			]
		}, {
			"x": 0,
			"y": 5,
			"z": 3,
			"elements": [
				"modularmachinery:blockcasing@2"
			]
		}, {
			"x": -2,
			"y": 1,
			"z": 1,
			"elements": [
				"modularmachinery:blockcasing@0"
			]
		}, {
			"x": -1,
			"y": 1,
			"z": 1,
			"elements": [
				"modularmachinery:blockcasing@0"
			]
		}, {
			"x": 3,
			"y": 9,
			"z": 5,
			"elements": [
				"thermalfoundation:fluid_cryotheum@0"
			]
		}, {
			"x": 1,
			"y": 5,
			"z": 3,
			"elements": [
				"modularmachinery:blockcasing@2"
			]
		}, {
			"x": 4,
			"y": 9,
			"z": 5,
			"elements": [
				"modularmachinery:blockcasing@0"
			]
		}, {
			"x": 2,
			"y": 5,
			"z": 3,
			"elements": [
				"modularmachinery:blockcasing@2"
			]
		}, {
			"x": 0,
			"y": 1,
			"z": 1,
			"elements": [
				"modularmachinery:blockcasing@0"
			]
		}, {
			"x": 5,
			"y": 9,
			"z": 5,
			"elements": [
				"mysticalagriculture:ingot_storage@6"
			]
		}, {
			"x": 3,
			"y": 5,
			"z": 3,
			"elements": [
				"modularmachinery:blockcasing@4"
			]
		}, {
			"x": 1,
			"y": 1,
			"z": 1,
			"elements": [
				"modularmachinery:blockcasing@0"
			]
		}, {
			"x": 4,
			"y": 5,
			"z": 3,
			"elements": [
				"modularmachinery:blockcasing@0"
			]
		}, {
			"x": 2,
			"y": 1,
			"z": 1,
			"elements": [
				"modularmachinery:blockcasing@0"
			]
		}, {
			"x": 5,
			"y": 5,
			"z": 3,
			"elements": [
				"mysticalagriculture:ingot_storage@6"
			]
		}, {
			"x": 3,
			"y": 1,
			"z": 1,
			"elements": [
				"modularmachinery:blockcasing@0"
			]
		}, {
			"x": 4,
			"y": 1,
			"z": 1,
			"elements": [
				"modularmachinery:blockcasing@0"
			]
		}, {
			"x": 5,
			"y": 1,
			"z": 1,
			"elements": [
				"xtones:zane@1"
			]
		}, {
			"x": -5,
			"y": 10,
			"z": 5,
			"elements": [
				"mysticalagriculture:ingot_storage@6"
			]
		}, {
			"x": -4,
			"y": 10,
			"z": 5,
			"elements": [
				"draconicevolution:infused_obsidian@0"
			]
		}, {
			"x": -5,
			"y": 6,
			"z": 3,
			"elements": [
				"xtones:zane@1"
			]
		}, {
			"x": -3,
			"y": 10,
			"z": 5,
			"elements": [
				"draconicevolution:infused_obsidian@0"
			]
		}, {
			"x": -4,
			"y": 6,
			"z": 3,
			"elements": [
				"modularmachinery:blockcasing@0"
			]
		}, {
			"x": -2,
			"y": 10,
			"z": 5,
			"elements": [
				"draconicevolution:draconium_block@1"
			]
		}, {
			"x": -5,
			"y": 2,
			"z": 1,
			"elements": [
				"xtones:zane@1"
			]
		}, {
			"x": -3,
			"y": 6,
			"z": 3,
			"elements": [
				"modularmachinery:blockcasing@4"
			]
		}, {
			"x": -1,
			"y": 10,
			"z": 5,
			"elements": [
				"mysticalagriculture:growth_accelerator@0"
			]
		}, {
			"x": 0,
			"y": 10,
			"z": 5,
			"elements": [
				"mysticalagriculture:growth_accelerator@0"
			]
		}, {
			"x": -4,
			"y": 2,
			"z": 1,
			"elements": [
				"modularmachinery:blockcasing@0"
			]
		}, {
			"x": -2,
			"y": 6,
			"z": 3,
			"elements": [
				"modularmachinery:blockcasing@2"
			]
		}, {
			"x": -3,
			"y": 2,
			"z": 1,
			"elements": [
				"modularmachinery:blockcasing@0"
			]
		}, {
			"x": -1,
			"y": 6,
			"z": 3,
			"elements": [
				"modularmachinery:blockcasing@2"
			]
		}, {
			"x": 1,
			"y": 10,
			"z": 5,
			"elements": [
				"mysticalagriculture:growth_accelerator@0"
			]
		}, {
			"x": 2,
			"y": 10,
			"z": 5,
			"elements": [
				"draconicevolution:draconium_block@1"
			]
		}, {
			"x": 0,
			"y": 6,
			"z": 3,
			"elements": [
				"modularmachinery:blockcasing@2"
			]
		}, {
			"x": -2,
			"y": 2,
			"z": 1,
			"elements": [
				"modularmachinery:blockcasing@0"
			]
		}, {
			"x": -1,
			"y": 2,
			"z": 1,
			"elements": [
				"modularmachinery:blockcasing@0"
			]
		}, {
			"x": 3,
			"y": 10,
			"z": 5,
			"elements": [
				"draconicevolution:infused_obsidian@0"
			]
		}, {
			"x": 1,
			"y": 6,
			"z": 3,
			"elements": [
				"modularmachinery:blockcasing@2"
			]
		}, {
			"x": 4,
			"y": 10,
			"z": 5,
			"elements": [
				"draconicevolution:infused_obsidian@0"
			]
		}, {
			"x": 2,
			"y": 6,
			"z": 3,
			"elements": [
				"modularmachinery:blockcasing@2"
			]
		}, {
			"x": 0,
			"y": 2,
			"z": 1,
			"elements": [
				"modularmachinery:blockcasing@0"
			]
		}, {
			"x": 5,
			"y": 10,
			"z": 5,
			"elements": [
				"mysticalagriculture:ingot_storage@6"
			]
		}, {
			"x": 3,
			"y": 6,
			"z": 3,
			"elements": [
				"modularmachinery:blockcasing@4"
			]
		}, {
			"x": 1,
			"y": 2,
			"z": 1,
			"elements": [
				"modularmachinery:blockcasing@0"
			]
		}, {
			"x": 4,
			"y": 6,
			"z": 3,
			"elements": [
				"modularmachinery:blockcasing@0"
			]
		}, {
			"x": 2,
			"y": 2,
			"z": 1,
			"elements": [
				"modularmachinery:blockcasing@0"
			]
		}, {
			"x": 5,
			"y": 6,
			"z": 3,
			"elements": [
				"xtones:zane@1"
			]
		}, {
			"x": 3,
			"y": 2,
			"z": 1,
			"elements": [
				"modularmachinery:blockcasing@0"
			]
		}, {
			"x": 4,
			"y": 2,
			"z": 1,
			"elements": [
				"modularmachinery:blockcasing@0"
			]
		}, {
			"x": 5,
			"y": 2,
			"z": 1,
			"elements": [
				"xtones:zane@1"
			]
		}, {
			"x": -5,
			"y": 11,
			"z": 5,
			"elements": [
				"extrautils2:cursedearth@0"
			]
		}, {
			"x": -4,
			"y": 11,
			"z": 5,
			"elements": [
				"extrautils2:cursedearth@0"
			]
		}, {
			"x": -5,
			"y": 7,
			"z": 3,
			"elements": [
				"xtones:zane@1"
			]
		}, {
			"x": -3,
			"y": 11,
			"z": 5,
			"elements": [
				"extrautils2:cursedearth@0"
			]
		}, {
			"x": -4,
			"y": 7,
			"z": 3,
			"elements": [
				"modularmachinery:blockcasing@0"
			]
		}, {
			"x": -2,
			"y": 11,
			"z": 5,
			"elements": [
				"extrautils2:cursedearth@0"
			]
		}, {
			"x": -5,
			"y": 3,
			"z": 1,
			"elements": [
				"mysticalagriculture:ingot_storage@6"
			]
		}, {
			"x": -3,
			"y": 7,
			"z": 3,
			"elements": [
				"modularmachinery:blockcasing@4"
			]
		}, {
			"x": -1,
			"y": 11,
			"z": 5,
			"elements": [
				"extrautils2:cursedearth@0"
			]
		}, {
			"x": 0,
			"y": 11,
			"z": 5,
			"elements": [
				"extrautils2:cursedearth@0"
			]
		}, {
			"x": -4,
			"y": 3,
			"z": 1,
			"elements": [
				"modularmachinery:blockcasing@0"
			]
		}, {
			"x": -2,
			"y": 7,
			"z": 3,
			"elements": [
				"modularmachinery:blockcasing@2"
			]
		}, {
			"x": -3,
			"y": 3,
			"z": 1,
			"elements": [
				"modularmachinery:blockcasing@0"
			]
		}, {
			"x": -1,
			"y": 7,
			"z": 3,
			"elements": [
				"modularmachinery:blockcasing@2"
			]
		}, {
			"x": 1,
			"y": 11,
			"z": 5,
			"elements": [
				"extrautils2:cursedearth@0"
			]
		}, {
			"x": 2,
			"y": 11,
			"z": 5,
			"elements": [
				"extrautils2:cursedearth@0"
			]
		}, {
			"x": 0,
			"y": 7,
			"z": 3,
			"elements": [
				"actuallyadditions:block_display_stand@0"
			]
		}, {
			"x": -2,
			"y": 3,
			"z": 1,
			"elements": [
				"modularmachinery:blockcasing@0"
			]
		}, {
			"x": -1,
			"y": 3,
			"z": 1,
			"elements": [
				"modularmachinery:blockcasing@0"
			]
		}, {
			"x": 3,
			"y": 11,
			"z": 5,
			"elements": [
				"extrautils2:cursedearth@0"
			]
		}, {
			"x": 1,
			"y": 7,
			"z": 3,
			"elements": [
				"modularmachinery:blockcasing@2"
			]
		}, {
			"x": 4,
			"y": 11,
			"z": 5,
			"elements": [
				"extrautils2:cursedearth@0"
			]
		}, {
			"x": 2,
			"y": 7,
			"z": 3,
			"elements": [
				"modularmachinery:blockcasing@2"
			]
		}, {
			"x": 0,
			"y": 3,
			"z": 1,
			"elements": [
				"modularmachinery:blockcasing@0"
			]
		}, {
			"x": 5,
			"y": 11,
			"z": 5,
			"elements": [
				"extrautils2:cursedearth@0"
			]
		}, {
			"x": 3,
			"y": 7,
			"z": 3,
			"elements": [
				"modularmachinery:blockcasing@4"
			]
		}, {
			"x": 1,
			"y": 3,
			"z": 1,
			"elements": [
				"modularmachinery:blockcasing@0"
			]
		}, {
			"x": 4,
			"y": 7,
			"z": 3,
			"elements": [
				"modularmachinery:blockcasing@0"
			]
		}, {
			"x": 2,
			"y": 3,
			"z": 1,
			"elements": [
				"modularmachinery:blockcasing@0"
			]
		}, {
			"x": 5,
			"y": 7,
			"z": 3,
			"elements": [
				"xtones:zane@1"
			]
		}, {
			"x": 3,
			"y": 3,
			"z": 1,
			"elements": [
				"modularmachinery:blockcasing@0"
			]
		}, {
			"x": 4,
			"y": 3,
			"z": 1,
			"elements": [
				"modularmachinery:blockcasing@0"
			]
		}, {
			"x": 5,
			"y": 3,
			"z": 1,
			"elements": [
				"mysticalagriculture:ingot_storage@6"
			]
		}, {
			"x": -5,
			"y": 8,
			"z": 3,
			"elements": [
				"xtones:zane@1"
			]
		}, {
			"x": -4,
			"y": 8,
			"z": 3,
			"elements": [
				"modularmachinery:blockcasing@0"
			]
		}, {
			"x": -5,
			"y": 4,
			"z": 1,
			"elements": [
				"mysticalagriculture:ingot_storage@6"
			]
		}, {
			"x": -3,
			"y": 8,
			"z": 3,
			"elements": [
				"modularmachinery:blockcasing@4"
			]
		}, {
			"x": -4,
			"y": 4,
			"z": 1,
			"elements": [
				"modularmachinery:blockcasing@0"
			]
		}, {
			"x": -2,
			"y": 8,
			"z": 3,
			"elements": [
				"extrautils2:compressedcobblestone@7"
			]
		}, {
			"x": -3,
			"y": 4,
			"z": 1,
			"elements": [
				"modularmachinery:blockcasing@0"
			]
		}, {
			"x": -1,
			"y": 8,
			"z": 3,
			"elements": [
				"extrautils2:compressedcobblestone@7"
			]
		}, {
			"x": 0,
			"y": 8,
			"z": 3,
			"elements": [
				"extrautils2:compressedcobblestone@7"
			]
		}, {
			"x": -2,
			"y": 4,
			"z": 1,
			"elements": [
				"modularmachinery:blockcasing@0"
			]
		}, {
			"x": -1,
			"y": 4,
			"z": 1,
			"elements": [
				"modularmachinery:blockcasing@0"
			]
		}, {
			"x": 1,
			"y": 8,
			"z": 3,
			"elements": [
				"extrautils2:compressedcobblestone@7"
			]
		}, {
			"x": 2,
			"y": 8,
			"z": 3,
			"elements": [
				"extrautils2:compressedcobblestone@7"
			]
		}, {
			"x": 0,
			"y": 4,
			"z": 1,
			"elements": [
				"modularmachinery:blockcasing@0"
			]
		}, {
			"x": 3,
			"y": 8,
			"z": 3,
			"elements": [
				"modularmachinery:blockcasing@4"
			]
		}, {
			"x": 1,
			"y": 4,
			"z": 1,
			"elements": [
				"modularmachinery:blockcasing@0"
			]
		}, {
			"x": 4,
			"y": 8,
			"z": 3,
			"elements": [
				"modularmachinery:blockcasing@0"
			]
		}, {
			"x": 2,
			"y": 4,
			"z": 1,
			"elements": [
				"modularmachinery:blockcasing@0"
			]
		}, {
			"x": 5,
			"y": 8,
			"z": 3,
			"elements": [
				"xtones:zane@1"
			]
		}, {
			"x": 3,
			"y": 4,
			"z": 1,
			"elements": [
				"modularmachinery:blockcasing@0"
			]
		}, {
			"x": 4,
			"y": 4,
			"z": 1,
			"elements": [
				"modularmachinery:blockcasing@0"
			]
		}, {
			"x": 5,
			"y": 4,
			"z": 1,
			"elements": [
				"mysticalagriculture:ingot_storage@6"
			]
		}, {
			"x": -5,
			"y": 9,
			"z": 3,
			"elements": [
				"mysticalagriculture:ingot_storage@6"
			]
		}, {
			"x": -4,
			"y": 9,
			"z": 3,
			"elements": [
				"modularmachinery:blockcasing@0"
			]
		}, {
			"x": -5,
			"y": 5,
			"z": 1,
			"elements": [
				"mysticalagriculture:ingot_storage@6"
			]
		}, {
			"x": -3,
			"y": 9,
			"z": 3,
			"elements": [
				"thermalfoundation:fluid_cryotheum@0"
			]
		}, {
			"x": -4,
			"y": 5,
			"z": 1,
			"elements": [
				"modularmachinery:blockcasing@0"
			]
		}, {
			"x": -2,
			"y": 9,
			"z": 3,
			"elements": [
				"extrautils2:compresseddirt@3"
			]
		}, {
			"x": -3,
			"y": 5,
			"z": 1,
			"elements": [
				"modularmachinery:blockcasing@0"
			]
		}, {
			"x": -1,
			"y": 9,
			"z": 3,
			"elements": [
				"extrautils2:compresseddirt@3"
			]
		}, {
			"x": 0,
			"y": 9,
			"z": 3,
			"elements": [
				"extrautils2:compresseddirt@3"
			]
		}, {
			"x": -2,
			"y": 5,
			"z": 1,
			"elements": [
				"modularmachinery:blockcasing@0"
			]
		}, {
			"x": -1,
			"y": 5,
			"z": 1,
			"elements": [
				"modularmachinery:blockcasing@0"
			]
		}, {
			"x": 1,
			"y": 9,
			"z": 3,
			"elements": [
				"extrautils2:compresseddirt@3"
			]
		}, {
			"x": 2,
			"y": 9,
			"z": 3,
			"elements": [
				"extrautils2:compresseddirt@3"
			]
		}, {
			"x": 0,
			"y": 5,
			"z": 1,
			"elements": [
				"modularmachinery:blockcasing@0"
			]
		}, {
			"x": 3,
			"y": 9,
			"z": 3,
			"elements": [
				"thermalfoundation:fluid_cryotheum@0"
			]
		}, {
			"x": 1,
			"y": 5,
			"z": 1,
			"elements": [
				"modularmachinery:blockcasing@0"
			]
		}, {
			"x": 4,
			"y": 9,
			"z": 3,
			"elements": [
				"modularmachinery:blockcasing@0"
			]
		}, {
			"x": 2,
			"y": 5,
			"z": 1,
			"elements": [
				"modularmachinery:blockcasing@0"
			]
		}, {
			"x": 5,
			"y": 9,
			"z": 3,
			"elements": [
				"mysticalagriculture:ingot_storage@6"
			]
		}, {
			"x": 3,
			"y": 5,
			"z": 1,
			"elements": [
				"modularmachinery:blockcasing@0"
			]
		}, {
			"x": 4,
			"y": 5,
			"z": 1,
			"elements": [
				"modularmachinery:blockcasing@0"
			]
		}, {
			"x": 5,
			"y": 5,
			"z": 1,
			"elements": [
				"mysticalagriculture:ingot_storage@6"
			]
		}, {
			"x": -5,
			"y": 10,
			"z": 3,
			"elements": [
				"mysticalagriculture:ingot_storage@6"
			]
		}, {
			"x": -4,
			"y": 10,
			"z": 3,
			"elements": [
				"draconicevolution:infused_obsidian@0"
			]
		}, {
			"x": -5,
			"y": 6,
			"z": 1,
			"elements": [
				"mysticalagriculture:ingot_storage@6"
			]
		}, {
			"x": -3,
			"y": 10,
			"z": 3,
			"elements": [
				"draconicevolution:infused_obsidian@0"
			]
		}, {
			"x": -4,
			"y": 6,
			"z": 1,
			"elements": [
				"modularmachinery:blockcasing@0"
			]
		}, {
			"x": -2,
			"y": 10,
			"z": 3,
			"elements": [
				"draconicevolution:draconium_block@1"
			]
		}, {
			"x": -3,
			"y": 6,
			"z": 1,
			"elements": [
				"modularmachinery:blockcasing@0"
			]
		}, {
			"x": -1,
			"y": 10,
			"z": 3,
			"elements": [
				"draconicevolution:draconium_block@1"
			]
		}, {
			"x": 0,
			"y": 10,
			"z": 3,
			"elements": [
				"draconicevolution:draconium_block@1"
			]
		}, {
			"x": -2,
			"y": 6,
			"z": 1,
			"elements": [
				"modularmachinery:blockcasing@0"
			]
		}, {
			"x": -1,
			"y": 6,
			"z": 1,
			"elements": [
				"modularmachinery:blockcasing@0"
			]
		}, {
			"x": 1,
			"y": 10,
			"z": 3,
			"elements": [
				"draconicevolution:draconium_block@1"
			]
		}, {
			"x": 2,
			"y": 10,
			"z": 3,
			"elements": [
				"draconicevolution:draconium_block@1"
			]
		}, {
			"x": 0,
			"y": 6,
			"z": 1,
			"elements": [
				"modularmachinery:blockcasing@0"
			]
		}, {
			"x": 3,
			"y": 10,
			"z": 3,
			"elements": [
				"draconicevolution:infused_obsidian@0"
			]
		}, {
			"x": 1,
			"y": 6,
			"z": 1,
			"elements": [
				"modularmachinery:blockcasing@0"
			]
		}, {
			"x": 4,
			"y": 10,
			"z": 3,
			"elements": [
				"draconicevolution:infused_obsidian@0"
			]
		}, {
			"x": 2,
			"y": 6,
			"z": 1,
			"elements": [
				"modularmachinery:blockcasing@0"
			]
		}, {
			"x": 5,
			"y": 10,
			"z": 3,
			"elements": [
				"mysticalagriculture:ingot_storage@6"
			]
		}, {
			"x": 3,
			"y": 6,
			"z": 1,
			"elements": [
				"modularmachinery:blockcasing@0"
			]
		}, {
			"x": 4,
			"y": 6,
			"z": 1,
			"elements": [
				"modularmachinery:blockcasing@0"
			]
		}, {
			"x": 5,
			"y": 6,
			"z": 1,
			"elements": [
				"mysticalagriculture:ingot_storage@6"
			]
		}, {
			"x": -5,
			"y": 11,
			"z": 3,
			"elements": [
				"extrautils2:cursedearth@0"
			]
		}, {
			"x": -4,
			"y": 11,
			"z": 3,
			"elements": [
				"extrautils2:cursedearth@0"
			]
		}, {
			"x": -5,
			"y": 7,
			"z": 1,
			"elements": [
				"mysticalagriculture:ingot_storage@6"
			]
		}, {
			"x": -3,
			"y": 11,
			"z": 3,
			"elements": [
				"extrautils2:cursedearth@0"
			]
		}, {
			"x": -4,
			"y": 7,
			"z": 1,
			"elements": [
				"modularmachinery:blockcasing@0"
			]
		}, {
			"x": -2,
			"y": 11,
			"z": 3,
			"elements": [
				"extrautils2:cursedearth@0"
			]
		}, {
			"x": -3,
			"y": 7,
			"z": 1,
			"elements": [
				"modularmachinery:blockcasing@0"
			]
		}, {
			"x": -1,
			"y": 11,
			"z": 3,
			"elements": [
				"extrautils2:cursedearth@0"
			]
		}, {
			"x": 0,
			"y": 11,
			"z": 3,
			"elements": [
				"extrautils2:cursedearth@0"
			]
		}, {
			"x": -2,
			"y": 7,
			"z": 1,
			"elements": [
				"modularmachinery:blockcasing@0"
			]
		}, {
			"x": -1,
			"y": 7,
			"z": 1,
			"elements": [
				"modularmachinery:blockcasing@0"
			]
		}, {
			"x": 1,
			"y": 11,
			"z": 3,
			"elements": [
				"extrautils2:cursedearth@0"
			]
		}, {
			"x": 2,
			"y": 11,
			"z": 3,
			"elements": [
				"extrautils2:cursedearth@0"
			]
		}, {
			"x": 0,
			"y": 7,
			"z": 1,
			"elements": [
				"modularmachinery:blockcasing@0"
			]
		}, {
			"x": 3,
			"y": 11,
			"z": 3,
			"elements": [
				"extrautils2:cursedearth@0"
			]
		}, {
			"x": 1,
			"y": 7,
			"z": 1,
			"elements": [
				"modularmachinery:blockcasing@0"
			]
		}, {
			"x": 4,
			"y": 11,
			"z": 3,
			"elements": [
				"extrautils2:cursedearth@0"
			]
		}, {
			"x": 2,
			"y": 7,
			"z": 1,
			"elements": [
				"modularmachinery:blockcasing@0"
			]
		}, {
			"x": 5,
			"y": 11,
			"z": 3,
			"elements": [
				"extrautils2:cursedearth@0"
			]
		}, {
			"x": 3,
			"y": 7,
			"z": 1,
			"elements": [
				"modularmachinery:blockcasing@0"
			]
		}, {
			"x": 4,
			"y": 7,
			"z": 1,
			"elements": [
				"modularmachinery:blockcasing@0"
			]
		}, {
			"x": 5,
			"y": 7,
			"z": 1,
			"elements": [
				"mysticalagriculture:ingot_storage@6"
			]
		}, {
			"x": -5,
			"y": 8,
			"z": 1,
			"elements": [
				"xtones:zane@1"
			]
		}, {
			"x": -4,
			"y": 8,
			"z": 1,
			"elements": [
				"modularmachinery:blockcasing@0"
			]
		}, {
			"x": -3,
			"y": 8,
			"z": 1,
			"elements": [
				"modularmachinery:blockcasing@0"
			]
		}, {
			"x": -2,
			"y": 8,
			"z": 1,
			"elements": [
				"modularmachinery:blockcasing@0"
			]
		}, {
			"x": -1,
			"y": 8,
			"z": 1,
			"elements": [
				"modularmachinery:blockcasing@0"
			]
		}, {
			"x": 0,
			"y": 8,
			"z": 1,
			"elements": [
				"modularmachinery:blockcasing@0"
			]
		}, {
			"x": 1,
			"y": 8,
			"z": 1,
			"elements": [
				"modularmachinery:blockcasing@0"
			]
		}, {
			"x": 2,
			"y": 8,
			"z": 1,
			"elements": [
				"modularmachinery:blockcasing@0"
			]
		}, {
			"x": 3,
			"y": 8,
			"z": 1,
			"elements": [
				"modularmachinery:blockcasing@0"
			]
		}, {
			"x": 4,
			"y": 8,
			"z": 1,
			"elements": [
				"modularmachinery:blockcasing@0"
			]
		}, {
			"x": 5,
			"y": 8,
			"z": 1,
			"elements": [
				"xtones:zane@1"
			]
		}, {
			"x": -5,
			"y": 9,
			"z": 1,
			"elements": [
				"xtones:zane@1"
			]
		}, {
			"x": -4,
			"y": 9,
			"z": 1,
			"elements": [
				"modularmachinery:blockcasing@0"
			]
		}, {
			"x": -3,
			"y": 9,
			"z": 1,
			"elements": [
				"modularmachinery:blockcasing@0"
			]
		}, {
			"x": -2,
			"y": 9,
			"z": 1,
			"elements": [
				"modularmachinery:blockcasing@0"
			]
		}, {
			"x": -1,
			"y": 9,
			"z": 1,
			"elements": [
				"modularmachinery:blockcasing@0"
			]
		}, {
			"x": 0,
			"y": 9,
			"z": 1,
			"elements": [
				"modularmachinery:blockcasing@0"
			]
		}, {
			"x": 1,
			"y": 9,
			"z": 1,
			"elements": [
				"modularmachinery:blockcasing@0"
			]
		}, {
			"x": 2,
			"y": 9,
			"z": 1,
			"elements": [
				"modularmachinery:blockcasing@0"
			]
		}, {
			"x": 3,
			"y": 9,
			"z": 1,
			"elements": [
				"modularmachinery:blockcasing@0"
			]
		}, {
			"x": 4,
			"y": 9,
			"z": 1,
			"elements": [
				"modularmachinery:blockcasing@0"
			]
		}, {
			"x": 5,
			"y": 9,
			"z": 1,
			"elements": [
				"xtones:zane@1"
			]
		}, {
			"x": -5,
			"y": 10,
			"z": 1,
			"elements": [
				"mysticalagriculture:ingot_storage@6"
			]
		}, {
			"x": -4,
			"y": 10,
			"z": 1,
			"elements": [
				"draconicevolution:infused_obsidian@0"
			]
		}, {
			"x": -3,
			"y": 10,
			"z": 1,
			"elements": [
				"draconicevolution:infused_obsidian@0"
			]
		}, {
			"x": -2,
			"y": 10,
			"z": 1,
			"elements": [
				"draconicevolution:infused_obsidian@0"
			]
		}, {
			"x": -1,
			"y": 10,
			"z": 1,
			"elements": [
				"draconicevolution:infused_obsidian@0"
			]
		}, {
			"x": 0,
			"y": 10,
			"z": 1,
			"elements": [
				"draconicevolution:infused_obsidian@0"
			]
		}, {
			"x": 1,
			"y": 10,
			"z": 1,
			"elements": [
				"draconicevolution:infused_obsidian@0"
			]
		}, {
			"x": 2,
			"y": 10,
			"z": 1,
			"elements": [
				"draconicevolution:infused_obsidian@0"
			]
		}, {
			"x": 3,
			"y": 10,
			"z": 1,
			"elements": [
				"draconicevolution:infused_obsidian@0"
			]
		}, {
			"x": 4,
			"y": 10,
			"z": 1,
			"elements": [
				"draconicevolution:infused_obsidian@0"
			]
		}, {
			"x": 5,
			"y": 10,
			"z": 1,
			"elements": [
				"mysticalagriculture:ingot_storage@6"
			]
		}, {
			"x": -5,
			"y": 11,
			"z": 1,
			"elements": [
				"extrautils2:cursedearth@0"
			]
		}, {
			"x": -4,
			"y": 11,
			"z": 1,
			"elements": [
				"extrautils2:cursedearth@0"
			]
		}, {
			"x": -3,
			"y": 11,
			"z": 1,
			"elements": [
				"extrautils2:cursedearth@0"
			]
		}, {
			"x": -2,
			"y": 11,
			"z": 1,
			"elements": [
				"extrautils2:cursedearth@0"
			]
		}, {
			"x": -1,
			"y": 11,
			"z": 1,
			"elements": [
				"extrautils2:cursedearth@0"
			]
		}, {
			"x": 0,
			"y": 11,
			"z": 1,
			"elements": [
				"extrautils2:cursedearth@0"
			]
		}, {
			"x": 1,
			"y": 11,
			"z": 1,
			"elements": [
				"extrautils2:cursedearth@0"
			]
		}, {
			"x": 2,
			"y": 11,
			"z": 1,
			"elements": [
				"extrautils2:cursedearth@0"
			]
		}, {
			"x": 3,
			"y": 11,
			"z": 1,
			"elements": [
				"extrautils2:cursedearth@0"
			]
		}, {
			"x": 4,
			"y": 11,
			"z": 1,
			"elements": [
				"extrautils2:cursedearth@0"
			]
		}, {
			"x": 5,
			"y": 11,
			"z": 1,
			"elements": [
				"extrautils2:cursedearth@0"
			]
		}, {
			"x": -5,
			"y": 0,
			"z": 10,
			"elements": [
				"mysticalagriculture:ingot_storage@6"
			]
		}, {
			"x": -4,
			"y": 0,
			"z": 10,
			"elements": [
				"mysticalagriculture:ingot_storage@6"
			]
		}, {
			"x": -3,
			"y": 0,
			"z": 10,
			"elements": [
				"mysticalagriculture:ingot_storage@6"
			]
		}, {
			"x": -2,
			"y": 0,
			"z": 10,
			"elements": [
				"mysticalagriculture:ingot_storage@6"
			]
		}, {
			"x": -1,
			"y": 0,
			"z": 10,
			"elements": [
				"mysticalagriculture:ingot_storage@6"
			]
		}, {
			"x": 0,
			"y": 0,
			"z": 10,
			"elements": [
				"mysticalagriculture:ingot_storage@6"
			]
		}, {
			"x": 1,
			"y": 0,
			"z": 10,
			"elements": [
				"mysticalagriculture:ingot_storage@6"
			]
		}, {
			"x": 2,
			"y": 0,
			"z": 10,
			"elements": [
				"mysticalagriculture:ingot_storage@6"
			]
		}, {
			"x": 3,
			"y": 0,
			"z": 10,
			"elements": [
				"mysticalagriculture:ingot_storage@6"
			]
		}, {
			"x": 4,
			"y": 0,
			"z": 10,
			"elements": [
				"mysticalagriculture:ingot_storage@6"
			]
		}, {
			"x": 5,
			"y": 0,
			"z": 10,
			"elements": [
				"mysticalagriculture:ingot_storage@6"
			]
		}, {
			"x": -5,
			"y": 1,
			"z": 10,
			"elements": [
				"mysticalagriculture:ingot_storage@6"
			]
		}, {
			"x": -4,
			"y": 1,
			"z": 10,
			"elements": [
				"xtones:zane@1"
			]
		}, {
			"x": -3,
			"y": 1,
			"z": 10,
			"elements": [
				"xtones:zane@1"
			]
		}, {
			"x": -2,
			"y": 1,
			"z": 10,
			"elements": [
				"mysticalagriculture:ingot_storage@6"
			]
		}, {
			"x": -1,
			"y": 1,
			"z": 10,
			"elements": [
				"mysticalagriculture:ingot_storage@6"
			]
		}, {
			"x": 0,
			"y": 1,
			"z": 10,
			"elements": [
				"mysticalagriculture:ingot_storage@6"
			]
		}, {
			"x": 1,
			"y": 1,
			"z": 10,
			"elements": [
				"mysticalagriculture:ingot_storage@6"
			]
		}, {
			"x": 2,
			"y": 1,
			"z": 10,
			"elements": [
				"mysticalagriculture:ingot_storage@6"
			]
		}, {
			"x": 3,
			"y": 1,
			"z": 10,
			"elements": [
				"xtones:zane@1"
			]
		}, {
			"x": 4,
			"y": 1,
			"z": 10,
			"elements": [
				"xtones:zane@1"
			]
		}, {
			"x": 5,
			"y": 1,
			"z": 10,
			"elements": [
				"mysticalagriculture:ingot_storage@6"
			]
		}, {
			"x": -5,
			"y": 2,
			"z": 10,
			"elements": [
				"mysticalagriculture:ingot_storage@6"
			]
		}, {
			"x": -4,
			"y": 2,
			"z": 10,
			"elements": [
				"xtones:zane@1"
			]
		}, {
			"x": -3,
			"y": 2,
			"z": 10,
			"elements": [
				"xtones:zane@1"
			]
		}, {
			"x": -2,
			"y": 2,
			"z": 10,
			"elements": [
				"xtones:zane@1"
			]
		}, {
			"x": -1,
			"y": 2,
			"z": 10,
			"elements": [
				"mysticalagriculture:ingot_storage@6"
			]
		}, {
			"x": 0,
			"y": 2,
			"z": 10,
			"elements": [
				"mysticalagriculture:ingot_storage@6"
			]
		}, {
			"x": 1,
			"y": 2,
			"z": 10,
			"elements": [
				"mysticalagriculture:ingot_storage@6"
			]
		}, {
			"x": 2,
			"y": 2,
			"z": 10,
			"elements": [
				"xtones:zane@1"
			]
		}, {
			"x": 3,
			"y": 2,
			"z": 10,
			"elements": [
				"xtones:zane@1"
			]
		}, {
			"x": 4,
			"y": 2,
			"z": 10,
			"elements": [
				"xtones:zane@1"
			]
		}, {
			"x": 5,
			"y": 2,
			"z": 10,
			"elements": [
				"mysticalagriculture:ingot_storage@6"
			]
		}, {
			"x": -5,
			"y": 3,
			"z": 10,
			"elements": [
				"mysticalagriculture:ingot_storage@6"
			]
		}, {
			"x": -4,
			"y": 3,
			"z": 10,
			"elements": [
				"mysticalagriculture:ingot_storage@6"
			]
		}, {
			"x": -3,
			"y": 3,
			"z": 10,
			"elements": [
				"xtones:zane@1"
			]
		}, {
			"x": -2,
			"y": 3,
			"z": 10,
			"elements": [
				"xtones:zane@1"
			]
		}, {
			"x": -1,
			"y": 3,
			"z": 10,
			"elements": [
				"xtones:zane@1"
			]
		}, {
			"x": 0,
			"y": 3,
			"z": 10,
			"elements": [
				"mysticalagriculture:ingot_storage@6"
			]
		}, {
			"x": 1,
			"y": 3,
			"z": 10,
			"elements": [
				"xtones:zane@1"
			]
		}, {
			"x": 2,
			"y": 3,
			"z": 10,
			"elements": [
				"xtones:zane@1"
			]
		}, {
			"x": 3,
			"y": 3,
			"z": 10,
			"elements": [
				"xtones:zane@1"
			]
		}, {
			"x": 4,
			"y": 3,
			"z": 10,
			"elements": [
				"mysticalagriculture:ingot_storage@6"
			]
		}, {
			"x": 5,
			"y": 3,
			"z": 10,
			"elements": [
				"mysticalagriculture:ingot_storage@6"
			]
		}, {
			"x": -5,
			"y": 4,
			"z": 10,
			"elements": [
				"mysticalagriculture:ingot_storage@6"
			]
		}, {
			"x": -4,
			"y": 4,
			"z": 10,
			"elements": [
				"mysticalagriculture:ingot_storage@6"
			]
		}, {
			"x": -5,
			"y": 0,
			"z": 8,
			"elements": [
				"mysticalagriculture:ingot_storage@6"
			]
		}, {
			"x": -3,
			"y": 4,
			"z": 10,
			"elements": [
				"mysticalagriculture:ingot_storage@6"
			]
		}, {
			"x": -4,
			"y": 0,
			"z": 8,
			"elements": [
				"modularmachinery:blockcasing@0"
			]
		}, {
			"x": -2,
			"y": 4,
			"z": 10,
			"elements": [
				"xtones:zane@1"
			]
		}, {
			"x": -3,
			"y": 0,
			"z": 8,
			"elements": [
				"modularmachinery:blockcasing@4"
			]
		}, {
			"x": -1,
			"y": 4,
			"z": 10,
			"elements": [
				"xtones:zane@1"
			]
		}, {
			"x": 0,
			"y": 4,
			"z": 10,
			"elements": [
				"xtones:zane@1"
			]
		}, {
			"x": -2,
			"y": 0,
			"z": 8,
			"elements": [
				"modularmachinery:blockcasing@4"
			]
		}, {
			"x": -1,
			"y": 0,
			"z": 8,
			"elements": [
				"modularmachinery:blockcasing@4"
			]
		}, {
			"x": 1,
			"y": 4,
			"z": 10,
			"elements": [
				"xtones:zane@1"
			]
		}, {
			"x": 0,
			"y": 0,
			"z": 8,
			"elements": [
				"modularmachinery:blockcasing@4"
			]
		}, {
			"x": 2,
			"y": 4,
			"z": 10,
			"elements": [
				"xtones:zane@1"
			]
		}, {
			"x": 3,
			"y": 4,
			"z": 10,
			"elements": [
				"mysticalagriculture:ingot_storage@6"
			]
		}, {
			"x": 1,
			"y": 0,
			"z": 8,
			"elements": [
				"modularmachinery:blockcasing@4"
			]
		}, {
			"x": 4,
			"y": 4,
			"z": 10,
			"elements": [
				"mysticalagriculture:ingot_storage@6"
			]
		}, {
			"x": 2,
			"y": 0,
			"z": 8,
			"elements": [
				"modularmachinery:blockcasing@4"
			]
		}, {
			"x": 5,
			"y": 4,
			"z": 10,
			"elements": [
				"mysticalagriculture:ingot_storage@6"
			]
		}, {
			"x": 3,
			"y": 0,
			"z": 8,
			"elements": [
				"modularmachinery:blockcasing@4"
			]
		}, {
			"x": 4,
			"y": 0,
			"z": 8,
			"elements": [
				"modularmachinery:blockcasing@0"
			]
		}, {
			"x": 5,
			"y": 0,
			"z": 8,
			"elements": [
				"mysticalagriculture:ingot_storage@6"
			]
		}, {
			"x": -5,
			"y": 5,
			"z": 10,
			"elements": [
				"mysticalagriculture:ingot_storage@6"
			]
		}, {
			"x": -4,
			"y": 5,
			"z": 10,
			"elements": [
				"mysticalagriculture:ingot_storage@6"
			]
		}, {
			"x": -5,
			"y": 1,
			"z": 8,
			"elements": [
				"xtones:zane@1"
			]
		}, {
			"x": -3,
			"y": 5,
			"z": 10,
			"elements": [
				"mysticalagriculture:ingot_storage@6"
			]
		}, {
			"x": -4,
			"y": 1,
			"z": 8,
			"elements": [
				"modularmachinery:blockcasing@0"
			]
		}, {
			"x": -2,
			"y": 5,
			"z": 10,
			"elements": [
				"mysticalagriculture:ingot_storage@6"
			]
		}, {
			"x": -3,
			"y": 1,
			"z": 8,
			"elements": [
				"modularmachinery:blockcasing@4"
			]
		}, {
			"x": -1,
			"y": 5,
			"z": 10,
			"elements": [
				"xtones:zane@1"
			]
		}, {
			"x": 0,
			"y": 5,
			"z": 10,
			"elements": [
				"xtones:zane@1"
			]
		}, {
			"x": -2,
			"y": 1,
			"z": 8,
			"elements": [
				"modularmachinery:blockcasing@4"
			]
		}, {
			"x": -1,
			"y": 1,
			"z": 8,
			"elements": [
				"modularmachinery:blockcasing@4"
			]
		}, {
			"x": 1,
			"y": 5,
			"z": 10,
			"elements": [
				"xtones:zane@1"
			]
		}, {
			"x": 2,
			"y": 5,
			"z": 10,
			"elements": [
				"mysticalagriculture:ingot_storage@6"
			]
		}, {
			"x": 0,
			"y": 1,
			"z": 8,
			"elements": [
				"modularmachinery:blockcasing@4"
			]
		}, {
			"x": 3,
			"y": 5,
			"z": 10,
			"elements": [
				"mysticalagriculture:ingot_storage@6"
			]
		}, {
			"x": 1,
			"y": 1,
			"z": 8,
			"elements": [
				"modularmachinery:blockcasing@4"
			]
		}, {
			"x": 4,
			"y": 5,
			"z": 10,
			"elements": [
				"mysticalagriculture:ingot_storage@6"
			]
		}, {
			"x": 2,
			"y": 1,
			"z": 8,
			"elements": [
				"modularmachinery:blockcasing@4"
			]
		}, {
			"x": 5,
			"y": 5,
			"z": 10,
			"elements": [
				"mysticalagriculture:ingot_storage@6"
			]
		}, {
			"x": 3,
			"y": 1,
			"z": 8,
			"elements": [
				"modularmachinery:blockcasing@4"
			]
		}, {
			"x": 4,
			"y": 1,
			"z": 8,
			"elements": [
				"modularmachinery:blockcasing@0"
			]
		}, {
			"x": 5,
			"y": 1,
			"z": 8,
			"elements": [
				"xtones:zane@1"
			]
		}, {
			"x": -5,
			"y": 6,
			"z": 10,
			"elements": [
				"mysticalagriculture:ingot_storage@6"
			]
		}, {
			"x": -4,
			"y": 6,
			"z": 10,
			"elements": [
				"mysticalagriculture:ingot_storage@6"
			]
		}, {
			"x": -5,
			"y": 2,
			"z": 8,
			"elements": [
				"xtones:zane@1"
			]
		}, {
			"x": -3,
			"y": 6,
			"z": 10,
			"elements": [
				"mysticalagriculture:ingot_storage@6"
			]
		}, {
			"x": -4,
			"y": 2,
			"z": 8,
			"elements": [
				"modularmachinery:blockcasing@0"
			]
		}, {
			"x": -2,
			"y": 6,
			"z": 10,
			"elements": [
				"xtones:zane@1"
			]
		}, {
			"x": -3,
			"y": 2,
			"z": 8,
			"elements": [
				"modularmachinery:blockcasing@4"
			]
		}, {
			"x": -1,
			"y": 6,
			"z": 10,
			"elements": [
				"xtones:zane@1"
			]
		}, {
			"x": 0,
			"y": 6,
			"z": 10,
			"elements": [
				"xtones:zane@1"
			]
		}, {
			"x": -2,
			"y": 2,
			"z": 8,
			"elements": [
				"modularmachinery:blockcasing@4"
			]
		}, {
			"x": -1,
			"y": 2,
			"z": 8,
			"elements": [
				"modularmachinery:blockcasing@4"
			]
		}, {
			"x": 1,
			"y": 6,
			"z": 10,
			"elements": [
				"xtones:zane@1"
			]
		}, {
			"x": 2,
			"y": 6,
			"z": 10,
			"elements": [
				"xtones:zane@1"
			]
		}, {
			"x": 0,
			"y": 2,
			"z": 8,
			"elements": [
				"modularmachinery:blockcasing@4"
			]
		}, {
			"x": 3,
			"y": 6,
			"z": 10,
			"elements": [
				"mysticalagriculture:ingot_storage@6"
			]
		}, {
			"x": 1,
			"y": 2,
			"z": 8,
			"elements": [
				"modularmachinery:blockcasing@4"
			]
		}, {
			"x": 4,
			"y": 6,
			"z": 10,
			"elements": [
				"mysticalagriculture:ingot_storage@6"
			]
		}, {
			"x": 2,
			"y": 2,
			"z": 8,
			"elements": [
				"modularmachinery:blockcasing@4"
			]
		}, {
			"x": 5,
			"y": 6,
			"z": 10,
			"elements": [
				"mysticalagriculture:ingot_storage@6"
			]
		}, {
